Workbook

Sheet Dashboard
B1: 1 | C1: 2 | D1: 3 | E1: 4 | F1: 5 | G1: 6 | H1: 7 | I1: 8 | J1: 9 | K1: 10 | L1: 11 | M1: 12 | N1: 13 | O1: 14 | P1: 15 | Q1: 16 | R1: 17 | S1: 18 | T1: 19 | U1: 20 | V1: 21 | W1: 22 | X1: 23 | Y1: 24 | Z1: 25 | AA1: 26 | AB1: 27
B2: PROJECT NAME - MIDREX TOLEDO HBI, OHIO USA | M2: CLIENT NAME - MIDREX INT | T2: STEEL CONTRACTOR - WH | AA2: DATE | AB2: =TODAY() -> 43146
B5: PROJECT SUMMARY | F5: PROGRESS CURVE | T5: CURRENT PROGRESS
B6: ='Project Summary'!B2 -> Contract Commencement | D6: ='Project Summary'!C2 -> 42736 | T6: 1
B7: ='Project Summary'!B3 -> Contract Completion | D7: ='Project Summary'!C3 -> 43099 | T7: 2
B8: ='Project Summary'!B4 -> Contract Duration | D8: ='Project Summary'!C4 -> 345 | T8: 3
B9: ='Project Summary'!B5 -> Elapsed Duration | D9: ='Project Summary'!C5 -> 150 | T9: 4
B10: ='Project Summary'!B6 -> Remaining Duration | D10: ='Project Summary'!C6 -> 195 | T10: 5
B11: ='Project Summary'!B7 -> Planned Progress (%) | D11: ='Project Summary'!C7 -> 0.43 | T11: 6
B12: ='Project Summary'!B8 -> Actual Progress (%) | D12: ='Project Summary'!C8 -> 0.48 | T12: 7
B13: ='Project Summary'!B9 -> Variation (%) | D13: ='Project Summary'!C9 -> -0.05 | T13: 8
B14: ='Project Summary'!B10 -> Slippage to Baseline | D14: ='Project Summary'!C10 -> -14 | T14: 9
B15: ='Project Summary'!B11 -> Forecast Completion | T15: 10
B16: PROJECT SUMMARY | F16: RESOURCE HISTOGRAM | T16: CRITICAL ISSUE
B17: PROJECT STATUS | T17: 1
T18: 2
T19: 3
T20: 4
T21: 5
B22: TIME CHART | T22: 6
T23: 7
T24: 8
T25: 9
T26: 10
B27: TECHNICAL SUBMITALS SUMMARY | I27: PROGRESS PHOTO'S
B28: Description | C28: Total | D28: Planned till date | E28: Submitted till date | F28: Approved | G28: Rejected | H28: Under Review
B29: Prequalification | C29: 24 | D29: 0 | E29: 0 | F29: 0 | G29: 0 | H29: 0
B30: Materials | C30: 67 | D30: 0 | E30: 0 | F30: 0 | G30: 0 | H30: 0
B31: Shop Drawings | C31: 112 | D31: 0 | E31: 0 | F31: 0 | G31: 0 | H31: 0
B32: RFI'S & NCR
B33: Description | C33: Raised | E33: Replied | G33: Status
B34: RFI
B35: NCR

Sheet Project Summary
H1: Progress Curve
B2: Contract Commencement | C2: 42736 | H2: Month | I2: 42736 | J2: 42767 | K2: 42795 | L2: 42826 | M2: 42856 | N2: 42887 | O2: 42917 | P2: 42948 | Q2: 42979 | R2: 43009 | S2: 43040 | T2: 43070 | U2: 43101 | V2: 43132 | W2: 43160 | X2: 43191 | Y2: 43221 | Z2: 43252 | AA2: 43282 | AB2: 43313
B3: Contract Completion | C3: =C2+(365+2)-4 -> 43099 | H3: Planned | I3: 0 | J3: 0 | K3: 0 | L3: 0 | M3: 0 | N3: 0 | O3: 0 | P3: 0 | Q3: 0 | R3: 0 | S3: 0 | T3: 0 | U3: 0 | V3: 0 | W3: 0 | X3: 0 | Y3: 0 | Z3: 0 | AA3: 0 | AB3: 0
B4: Contract Duration | C4: 345 | H4: Actual | I4: 0 | J4: 0 | K4: 0 | L4: 0 | M4: 0 | N4: 0 | O4: 0 | P4: 0 | Q4: 0 | R4: 0 | S4: 0 | T4: 0 | U4: 0 | V4: 0 | W4: 0 | X4: 0 | Y4: 0 | Z4: 0 | AA4: 0 | AB4: 0
B5: Elapsed Duration | C5: 150 | H5: Planned Cum. | I5: =I3 -> 0 | J5: =I5+J3 -> 0 | K5: =J5+K3 -> 0 | L5: =K5+L3 -> 0 | M5: =L5+M3 -> 0 | N5: =M5+N3 -> 0 | O5: =N5+O3 -> 0 | P5: =O5+P3 -> 0 | Q5: =P5+Q3 -> 0 | ... AB5: =AA5+AB3 -> 0
B6: Remaining Duration | C6: 195 | H6: Actual Cum. | I6: =I4 -> 0 | J6: =I6+J4 -> 0 | K6: =J6+K4 -> 0 | L6: =K6+L4 -> 0 | M6: =L6+M4 -> 0 | N6: =M6+N4 -> 0 | O6: =N6+O4 -> 0 | P6: =O6+P4 -> 0 | Q6: =P6+Q4 -> 0 | ... AB6: =AA6+AB4 -> 0
B7: Planned Progress (%) | C7: =C19 -> 0.43
B8: Actual Progress (%) | C8: =C20 -> 0.48
B9: Variation (%) | C9: =C7-C8 -> -0.05
B10: Slippage to Baseline | C10: =-14 -> -14 | H10: Resource Histogram
B11: Forecast Completion | H11: Month | I11: 42736 | J11: 42767 | K11: 42795 | L11: 42826 | M11: 42856 | N11: 42887 | O11: 42917 | P11: 42948 | Q11: 42979 | R11: 43009 | S11: 43040 | T11: 43070 | U11: 43101 | V11: 43132 | W11: 43160 | X11: 43191 | Y11: 43221 | Z11: 43252 | AA11: 43282 | AB11: 43313
H12: Planned | I12: ='Daily Manpower'!P33 -> 0 | J12: ='Daily Manpower'!P61 -> 0 | K12: 0 | L12: 0 | M12: 0 | N12: 0 | O12: 0 | P12: 0 | Q12: 0 | R12: 0 | S12: 0 | T12: 0 | U12: 0 | V12: 0 | W12: 0 | X12: 0 | Y12: 0 | Z12: 0 | AA12: 0 | AB12: 0
H13: Actual | I13: ='Daily Manpower'!O33 -> 0 | J13: ='Daily Manpower'!O61 -> 0 | K13: 0 | L13: 0 | M13: 0 | N13: 0 | O13: 0 | P13: 0 | Q13: 0 | R13: 0 | S13: 0 | T13: 0 | U13: 0 | V13: 0 | W13: 0 | X13: 0 | Y13: 0 | Z13: 0 | AA13: 0 | AB13: 0
H14: Planned Cum. | I14: =I12 -> 0 | J14: =I14+J12 -> 0 | K14: =J14+K12 -> 0 | L14: =K14+L12 -> 0 | M14: =L14+M12 -> 0 | N14: =M14+N12 -> 0 | O14: =N14+O12 -> 0 | P14: =O14+P12 -> 0 | Q14: =P14+Q12 -> 0 | ... AB14: =AA14+AB12 -> 0
H15: Actual Cum. | I15: =I13 -> 0 | J15: =I15+J13 -> 0 | K15: =J15+K13 -> 0 | L15: =K15+L13 -> 0 | M15: =L15+M13 -> 0 | N15: =M15+N13 -> 0 | O15: =N15+O13 -> 0 | P15: =O15+P13 -> 0 | Q15: =P15+Q13 -> 0 | ... AB15: =AA15+AB13 -> 0
B16: Elapsed Dur % | C16: =C7/C6 -> 0.0022051282
B17: Remaining Dur % | C17: =C8/C6 -> 0.0024615385
B19: Planned Progress (%) | C19: 0.43
B20: Actual Progress (%) | C20: 0.48
C23: 345
C24: 150
C25: =C23-C24 -> 195
B26: Planned Progress (%) | C26: =C36 -> 0
B27: Actual Progress (%) | C27: =C37 -> 0
B28: Variation (%) | C28: =C26-C27 -> 0
B29: Slippage to Baseline | C29: 14

Sheet Daily Manpower
B2: Date | C2: Steel Fixer | D2: Carpenter | E2: Mason | F2: Welder | G2: Helper | H2: Rigger | I2: Electrician | J2: Plumber | K2: Painter | L2: Guinter | M2: Waterproof Tech. | O2: Actual | P2: Plan
B3: 42736
B4: 42737
B5: 42738
B6: 42739
B7: 42740
B8: 42741
B9: 42742
B10: 42743
B11: 42744
B12: 42745
B13: 42746
B14: 42747
... B32: 42765
B33: 42766 | O33: =IFERROR(SUM(C3:M33),0) -> 0 | P33: 0
B34: 42767
B35: 42768
B36: 42769
B37: 42770
B38: 42771
B39: 42772
B40: 42773
B41: 42774
B42: 42775
B43: 42776
B44: 42777
B45: 42778
... B60: 42793
B61: 42794 | O61: =IFERROR(AVERAGE(C34:M61),0) -> 0 | P61: 0
B62: 42795
B63: 42796
B64: 42797
B65: 42798
B66: 42799
B67: 42800
B68: 42801
B69: 42802
B70: 42803
B71: 42804
B72: 42805
...

Sheet Sheet4
