Workbook
Name _SDA3: '[1]Material Submittal'!#REF!
Name _SDA3: '[1]Material Submittal'!#REF!
Name _SDA3: '[1]Material Submittal'!#REF!
Name _SDA3: '[1]Material Submittal'!#REF!
Name _SDA3: '[1]Material Submittal'!#REF!
Name AB: #REF!
Name AB: #REF!
Name AB: #REF!
Name AB: #REF!
Name AB: #REF!
Name abb: #REF!
Name abb: #REF!
Name ABS: #REF!
Name ABS: #REF!
Name ABS: #REF!
Name ABS: #REF!
Name ABS: #REF!
Name As: #REF!
Name As: #REF!
Name As: #REF!
Name As: #REF!
Name As: #REF!
Name Bui: #REF!
Name Bui: #REF!
Name Bui: #REF!
Name Bui: #REF!
Name Bui: #REF!
Name bUYSAAS\: #REF!
Name bUYSAAS\: #REF!
Name bUYSAAS\: #REF!
Name bUYSAAS\: #REF!
Name bUYSAAS\: #REF!
Name dt: #REF!
Name dt: #REF!
Name dt: #REF!
Name dt: #REF!
Name dt: #REF!
Name jn: #REF!
Name jn: #REF!
Name jn: #REF!
Name jn: #REF!
Name jn: #REF!
Name OM: #REF!
Name OM: #REF!
Name OM: #REF!
Name OM: #REF!
Name OM: #REF!
Name Operation: #REF!
Name Operation: #REF!
Name Operation: #REF!
Name Operation: #REF!
Name Operation: #REF!
Name sd_table_ax102: #REF!
Name sd_table_ax102: #REF!
Name sd_table_ax102: #REF!
Name sd_table_ax102: #REF!
Name sd_table_ax102: #REF!
Name TEST: '[1]Material Submittal'!#REF!
Name TEST: '[1]Material Submittal'!#REF!
Name TEST: '[1]Material Submittal'!#REF!

Sheet Monthly Dashboard Report
B1: Engineering Enterprises MONTHLY PROJECT DASHBOARD | R1: Doc. No. | T1: REE/OPR/05
R2: Rev.: | T2: 0
R3: Date: | T3: =+'Cover '!T11 -> 42460
A4: Project: | B4: AL JASASSIYA SOUTH HOUSE PROJECT (PROJECT #R67-M1-15) | R4: Report for the Month of: | T4: =+T3 -> 42460
A5: Client: | B5: PRIVATE ENGINEERING OFFICE | J5: Consultant: | L5: M/S DORSCH QATAR | P5: Main Contractor | R5: URBACON TRADING & CONTRACTING
A7: 1. Schedule | K7: 7. Scope Management
A8: Program Details | B8: Plan Start | C8: Completion Date | E8: Plan % | F8: Actual % | G8: Variance % | H8: Target (Next Month) | K8: Current Scope Value (CSV) | N8: Expected Contract Value | Q8: Project Revenue
C9: Plan | D9: Projected
A10: MEP Base Line | B10: =+'2-Schedule'!AG11 -> 42086 | C10: =+'2-Schedule'!AT11 -> 42338 | D10: =+D11 -> 42518 | E10: 1 | F10: =+F11 -> 0.9495 | G10: =+F10-E10 -> -0.0505 | H10: 0.985 | K10: Original Contract Value | M10: =+'7-Project Scope +Revenue Detail'!C8 -> 49200000 | N10: Current Scope Value | P10: =M17 -> 52051339 | Q10: Planned Claim upto this month | T10: =+'7-Project Scope +Revenue Detail'!E21 -> 49354914
A11: MEP Revised | B11: =+B10 -> 42086 | C11: =+'2-Schedule'!AT12 -> 42424 | D11: =+'2-Schedule'!BK12 -> 42518 | E11: =+'2-Schedule'!Z24 -> 1 | F11: =+'2-Schedule'!AJ24 -> 0.9495 | G11: =+F11-E11 -> -0.0505 | H11: 0.985 | K11: B O Q Adjustment (Revised BOQ) | M11: =+'7-Project Scope +Revenue Detail'!C9 -> 0 | N11: Exp. Re-measured Qty | Q11: Actual Claim (EV) upto this month | T11: =+'7-Project Scope +Revenue Detail'!E23 -> 44408504
K12: Approved Variations | M12: =+'7-Project Scope +Revenue Detail'!C10 -> 154913.84 | N12: Variations Awaiting Approval (not Under Execution) | P12: =+'7.2-Scope Management'!C24 -> 0 | Q12: Certified | T12: =+'7.1-Payment-Detail'!D19 -> 40992024
K13: Approved Deletions | M13: =+'7-Project Scope +Revenue Detail'!C11 -> 0 | N13: EOT- (Submitted) | Q13: Planned Claim of this month | T13: =+'7-Project Scope +Revenue Detail'!E20 -> 154913.84
K14: Additions due to re- measurement | M14: =+'7-Project Scope +Revenue Detail'!C13 -> 0 | N14: Expected New Variations (not Under Execution) | P14: =+'7-Project Scope +Revenue Detail'!H12 -> 0 | Q14: Actual Claim of this month | T14: =+'7.1-Payment-Detail'!C17 -> 3416480.8
A15: VO Scope | K15: Variations under execution & awaiting Approval | M15: =+'7-Project Scope +Revenue Detail'!C12 -> 2696425.1 | N15: Expected back charges | P15: =+-'9-Budget-Cost-ETC-EAC'!E27 -> 0
A17: Variance Analysis | K17: Total (QAR) | M17: =SUM(M10:M16) -> 52051339 | N17: Total (QAR) | P17: =SUM(P10:P16) -> 52051339
A19: 2. Engineering | K19: 8. HSE - Health Safety Environment
B20: Total | C20: Plan-Approval | D20: Actual-Approval | F20: Rejected | G20: Under Review | H20: Balance to Submit | I20: EDC to 100% Approval | O20: Man-Hours Worked | P20: Man-Hours without LTI | Q20: Man-Hours without LTA | R20: First Aid Case | S20: Major Injuries | T20: Medical Case
A21: Design Drawings | K21: This Month | O21: =+'8-HSE'!AG9 -> 51440 | P21: =+'8-HSE'!AG10 -> 51440 | Q21: =+'8-HSE'!AG11 -> 51440 | R21: =+'8-HSE'!AG12 -> 3 | S21: =+'8-HSE'!AG13 -> 0 | T21: =+'8-HSE'!AG14 -> 5
A22: Shop Drawings | B22: =+'3-Engineering'!B20 -> 514 | C22: =+B22 -> 514 | D22: =+'3-Engineering'!E20 -> 514 | E22: =+D22/B22 -> 1 | F22: =+'3-Engineering'!F20 -> 0 | G22: =+'3-Engineering'!G20 -> 0 | H22: =+B22-D22-F22-G22 -> 0 | K22: Till Last Month | O22: =+'8-HSE'!R9 -> 11380000 | P22: =+'8-HSE'!R10 -> 11380000 | Q22: =+'8-HSE'!R11 -> 11380000 | R22: =+'8-HSE'!R12 -> 39 | S22: =+'8-HSE'!R13 -> 0 | T22: =+'8-HSE'!R14 -> 36
K23: Total | O23: =SUM(O21:O22) -> 11431440 | P23: =SUM(P21:P22) -> 11431440 | Q23: =SUM(Q21:Q22) -> 11431440 | R23: =SUM(R21:R22) -> 42 | S23: =SUM(S21:S22) -> 0 | T23: =SUM(T21:T22) -> 41
A25: 3. Procurement | K25: 9. Cost Control
A26: Material Submission | D26: Material Purchase Order | G26: Material Delivery | N26: BAC- Budget At Completion (Including under execution) | P26: AC- Actual Cost | Q26: ETC- Estimate To Complete | R26: EAC-Estimate At Completion = ETC+AC | S26: Expected Gross Profit/ Loss
N27: Original Contract | O27: VO + Add. Qty | S27: CSV - EAC
A28: Total | C28: =+'4-Procurement'!K25 -> 109 | D28: Total | F28: =+C28 -> 109 | G28: Total | I28: 109 | K28: Material | N28: 25830769 | O28: =+'9-Budget-Cost-ETC-EAC'!C12 -> 1123129.4 | P28: =+'9-Budget-Cost-ETC-EAC'!D13 -> 26667132 | Q28: =+'9-Budget-Cost-ETC-EAC'!E13 -> 260000 | R28: =Q28+P28 -> 26927132 | S28: CSV | T28: =M17 -> 52051339
A29: Plan-Approval | C29: =+C28 -> 109 | D29: Plan - PO's | F29: =+'4-Procurement'!K25 -> 109 | G29: Plan-Delivery | I29: 109 | K29: Labour | N29: 6180000 | O29: =+'9-Budget-Cost-ETC-EAC'!C18 -> 1306043.7 | P29: =+'9-Budget-Cost-ETC-EAC'!D19 -> 14217600 | Q29: =+'9-Budget-Cost-ETC-EAC'!E19 -> 514800 | R29: =Q29+P29 -> 14732400 | S29: EAC | T29: =R34 -> 49996902
A30: Actual-Approval | C30: =+C29 -> 109 | D30: PR-Released | F30: =+F29 -> 109 | G30: Actual-Delivered | I30: 109 | K30: Preliminaries/ Staff | N30: 6222000 | O30: =+'9-Budget-Cost-ETC-EAC'!C21 -> 222829.59 | P30: =+'9-Budget-Cost-ETC-EAC'!D20 -> 3721391.3 | Q30: =+'9-Budget-Cost-ETC-EAC'!E20 -> 150000 | R30: =Q30+P30 -> 3871391.3
D31: Actual- PO's | F31: =+F30 -> 109 | G31: Delivery-Confirmed | I31: 109 | K31: Sub-contract/Site Over Head | N31: 2434887.3 | P31: =+'9-Budget-Cost-ETC-EAC'!D25 -> 3315978.2 | Q31: =+'9-Budget-Cost-ETC-EAC'!E25 -> 150000 | R31: =Q31+P31 -> 3465978.2
A32: Variance | C32: =+C30-C28 -> 0 | D32: Variance | F32: =+F31-F29 -> 0 | G32: Variance | I32: =+I31-I28 -> 0 | K32: Total -Budget | N32: =SUM(N28:N31) -> 40667656 | O32: =SUM(O28:O31) -> 2652002.6 | P32: =SUM(P28:P31) -> 47922102 | Q32: =SUM(Q28:Q31) -> 1074800 | R32: =Q32+P32 -> 48996902
A33: Expected Date to 100% Approval | K33: <Back Charges/ Scope Deleation> (if any) | Q33: ='9-Budget-Cost-ETC-EAC'!E28 -> 1000000 | R33: =Q33+P33 -> 1000000
K34: G. Total Budget (QAR) | O34: =N32+O32 -> 43319659 | P34: =SUM(P28:P31)+P33 -> 47922102 | Q34: =SUM(Q28:Q31)+Q33 -> 2074800 | R34: =SUM(R28:R31)+R33 -> 49996902 | S34: =T34/T28 -> 0.039469441 | T34: =T28-T29 -> 2054437.3
A36: 4. QA/ QC | K36: 10. Resources
A37: Inspection By the Engineer | F37: NCR- Non Conformance Report | M37: Manpower (This Month) | P37: Man Hours (Cumulative) | S37: Mob/ DE Mob Plan (Next Month)
B38: Installation Inspection | D38: Material Inspection | H38: Internal | I38: External | M38: Plan | N38: Actual | O38: Variance | P38: Plan | Q38: Actual | R38: Variance | S38: Mobilization | T38: Demobilization
A39: Total | B39: =SUM(B40:B42) -> 1131 | D39: =SUM(D40:D42) -> 57 | F39: Total-Received | H39: =+'5-QA-QC'!K29 -> 0 | I39: =+'5-QA-QC'!K28 -> 29 | K39: Staff | M39: =+'10-Resources'!R11 -> 15 | N39: =+'10-Resources'!X11 -> 10 | O39: =N39-M39 -> -5 | Q39: =+'10-Resources'!AJ11+'10-Resources'!AV11 -> 74776 | R39: =P39-Q39 -> -74776 | T39: ='10-Resources'!BN11 -> 4
A40: Approved | B40: =+'5-QA-QC'!W23 -> 672 | C40: =B40/B39 -> 0.59416446 | D40: =+'5-QA-QC'!W14 -> 57 | E40: =D40/D39 -> 1 | F40: Closed | H40: =+'5-QA-QC'!AA29 -> 0 | I40: =+'5-QA-QC'!AA28 -> 11 | K40: Manpower | M40: =+'10-Resources'!R16 -> 40 | N40: =+'10-Resources'!X16 -> 141 | O40: =+M40-N40 -> -101 | P40: 9490000 | Q40: =+'10-Resources'!AJ12+'10-Resources'!AV16+'10-Resources'!AV17 -> 11348124 | R40: =+P40-Q40 -> -1858124 | T40: ='10-Resources'!BN16 -> 65
A41: Open | B41: =+'5-QA-QC'!AI23 -> 407 | C41: =B41/B39 -> 0.35985853 | D41: =+'5-QA-QC'!AI14 -> 0 | E41: =D41/D39 -> 0 | F41: Open | H41: =+H39-H40 -> 0 | I41: =I39-I40 -> 18 | K41: Sub Con. | Q41: =N41*10*26 -> 0 | T41: ='10-Resources'!BN17 -> 0
A42: Rejected | B42: =+'5-QA-QC'!AU23 -> 52 | C42: =B42/B39 -> 0.045977011 | D42: =+'5-QA-QC'!AU14 -> 0 | E42: =D42/D39 -> 0
A45: 5. Construction | E45: 6. Areas of Concern | K45: 11. Close-out
A46: Milestones and Major Ongoing Activities Status | E46: Areas of Concern (Critical only) | L46: Installation Inspection | M46: Material Inspection | N46: Red Line Drw | O46: As-Built | P46: T&C Procedure | Q46: O&M Manual | R46: Training Manual | S46: Warranties | T46: Spare Parts
A47: =IF(+'6-Construction'!B8="","",+'6-Construction'!B8) -> Testing & Commissioning of Fire fighting system in progress. | E47: =+IF('13-AOC'!B9="","",'13-AOC'!B9) -> Delivery of Emergency lights for staircase in Palace, chalets & Ancillary buildings | K47: Total | L47: =+'14-Close-out'!C10 -> 1131 | M47: =+'14-Close-out'!C6 -> 64 | O47: =+'14-Close-out'!C18 -> 457 | P47: =+'14-Close-out'!C23 -> 15 | Q47: =+'14-Close-out'!C33 -> 21
...

Sheet Cover 
O9: Doc. No.: | T9: REE/OPR/05
O10: Rev.: | T10: 0
O11: Date: | T11: 42460

Sheet Index
I1: INDEX
E5: 1 | F5: 1 | L5: Executive Project Summary
E6: 2 | F6: 2 | L6: Schedule
L7: § Program
L8: § Progress
E9: 2 | F9: 3 | L9: Engineering
L10: § Shop Drawings
L11: § Technical Queries (TQ/ SCR/ RFI )
E12: 3 | F12: 4 | L12: Procurement
L13: § Material Submittals
L14: § Material Purchase Orders
H15: 4.1 | L15: § Logs
H16: 4.12 | L16: § Long Lead Tracking
E17: 4 | F17: 5 | L17: QA/QC Status
L18: § Material Inspection
L19: § Installation Inspection
L20: § Non-conformance Report
E21: 5 | F21: 6 | L21: Construction
L22: § Progress Accomplished This Month (Major Activities only)
L23: § One Month Look Ahead Plan (Major Activities only)
L24: § Progress S-Curve
L25: § Site Photos
E26: 6 | F26: 7 | L26: Commercial
H27: 7.1 | L27: § Payment Application Detail
H28: 7.2 | L28: § Scope Management Matrix (VO)
H29: 7.3 | L29: § Sub-contractor
H30: 7.4 | L30: § 7.4-Back Chargs detail
E31: 7 | F31: 8 | L31: HSE - Report
L32: § HSE Report
L33: § PPE Update
E34: 8 | F34: 9 | L34: Earned Value Management
L35: § Budget / Cost Comparison
L36: § ETC - Estimate to Complete + EAC -Estimate At Completion
E37: 9 | F37: 10 | L37: Resources
L38: § Man-hours
L39: § STB Update
L40: § Histogram
E41: 10 | F41: 11 | L41: Accounts
E42: 11 | F42: 12 | L42: Store
E43: 12 | F43: 13 | L43: Areas of Concern
...

Sheet 1-Executive Project Summary
A1: EXECUTIVE PROJECT SUMMARY - R67-M1-15
A2: Project Name | D2: Project Scope | E2: Report Date
A3: AL JASASSIYA SOUTH HOUSE PROJECT | D3: MEP | E3: =+'Cover '!T11 -> 42460
A5: Project Overview
A7: The project is a palace on a beautiful site to the north of Qatar. The project consist of Palace, 6 No of Chalets, Main Gate, Service Gate, Staff Quarter, Main Kitchen and Garage, Service Yard, Horse Stable, Covered Traces and External Works.
A9: 1:Progress/Schedule:
A11: MEP Over all progress is 94.95% as of 31-Mar-16 against planned progress of 100.00%
A12: Compared to last Month progress 92.88% against planned 100.00%.
A13: Over all progress Engineering - 100.00%, Procurement - 100.00%, Construction - 98.37% and T&C - 24%.
A15: Ongoing key works-Progress:
A17: The Following is a List the major works that are under progress on site.
A19: Ø Testing & Commissioning of Fire fighting system in progress
A20: Ø Pretesting of HVAC Equipment in progress
A21: Ø Testing & Commissioning of Electrical Equipment in progress
A22: Ø Pretesting of panels in progress.
... A35: 4- QA/QC:
A37: Ø Number of open and closed NCR’s | C37: =+'5-QA-QC'!K28 -> 29
A38: Ø Number of IR thismonth
A41: 5- Construction
A43: Construction Progress:
A44: Building / Area | B44: Planned % | C44: Actual % | D44: Variance
A46: Chalets – 6nos | B46: 1 | C46: 0.9888 | D46: =+C46-B46 -> -0.0112
A47: Main Palace | B47: 1 | C47: 0.9818 | D47: =+C47-B47 -> -0.0182
A48: Main Gate | B48: 1 | C48: 0.9846 | D48: =+C48-B48 -> -0.0154
A49: Service Gate | B49: 1 | C49: 0.9877 | D49: =+C49-B49 -> -0.0123
A50: Staff Quarter | B50: 1 | C50: 0.9843 | D50: =+C50-B50 -> -0.0157
A51: Horse Stable | B51: 1 | C51: 0.9882 | D51: =+C51-B51 -> -0.0118
A52: Garage & Kitchen | B52: 1 | C52: 0.9543 | D52: =+C52-B52 -> -0.0457
A53: Service Yard | B53: 1 | C53: 0.9777 | D53: =+C53-B53 -> -0.0223
A54: Substation | B54: 1 | C54: 0.9913 | D54: =+C54-B54 -> -0.0087
A55: External | B55: 1 | C55: 0.9957 | D55: =+C55-B55 -> -0.0043
A56: Over All | B56: 1 | C56: 0.9837 | D56: =+C56-B56 -> -0.0163
A58: Testing & Commissioning Progress
A59: Project | B59: Planned % | C59: Actual % | D59: Variance
A61: AJSH | B61: 1 | C61: 0.24 | D61: =+C61-B61 -> -0.76
A63: 6- Commercial
A65: Gross Certified Amount up to date | C65: =+'7.1-Payment-Detail'!D19 -> 40992024
A67: 7- HSE
A69: No Safety Issues
A71: 8- Earned Value Management
...

Sheet 2-Schedule
I1: R67-M1-15 - Monthly Project Report SCHEDULE | BI1: Doc. No.: | BO1: REE/OPR/05.1
BI2: Rev.: | BK2: Rev.: | BO2: 0
BI3: Date: | BO3: =+'Cover '!T11 -> 42460
A5: Project Overview
A8: Program Details
A10: Program Detail | Q10: Rev | U10: Status | AG10: Start Date | AT10: Plan Completion Date | BK10: Projected Completion Date
A11: MEP Baseline | Q11: 1 | U11: Approved | AG11: 42086 | AT11: 42338
A12: MEP Revised (Target) | Q12: 2 | U12: Submitted | AG12: 42086 | AT12: 42424 | BK12: 42518
A14: Delay Period | AT14: -94days (As per MEP Revised Program-2)
A16: (A)- Approved, (F) - Followed, (S)-Submitted/under review
A18: Progress Details
A20: Month | Q20: Progress Type | Z20: Plan | AJ20: Actual | AT20: Variance
AT21: Total | BB21: Engineering | BK21: Procurement | BT21: Construction
A22: Previous | I22: 42400 | Q22: Physical | Z22: 1 | AJ22: 0.9288 | AL22: #VALUE! | AT22: =AJ22-Z22 -> -0.0712 | BB22: 0 | BH22: =97.17%-92.81% -> 0.0436 | BK22: =99.98%-100% -> -0.0002 | BT22: =95.88%-100% -> -0.0412
Q23: Financial | AJ23: 0.8581 | AT23: =AJ23-Z22 -> -0.1419
A24: Current | I24: 42429 | Q24: Physical | Z24: 1 | AJ24: 0.9495 | AL24: =AB24-Q24 -> #VALUE! | AT24: =AJ24-Z24 -> -0.0505 | BB24: =100%-100% -> 0 | BH24: =97.17%-92.81% -> 0.0436 | BK24: 0 | BT24: =98.37%-100% -> -0.0163
Q25: Financial | AJ25: 0.9 | AT25: =AJ25-Z24 -> -0.1
A26: Forecast | I26: 42459 | Q26: Physical | Z26: 1
Q27: Financial
A29: Remarks

Sheet 3-Engineering
B1: R6-M1-15 - Monthly Project Report ENGINEERING | H1: Doc. No.: | I1: REE/OPR/05.2
H2: Rev.: | I2: 0
H3: Date: | I3: =+'Cover '!T11 -> 42460
A5: As of: | B5: =I3 -> 42460
A6: Shop Drawings
A8: Description | B8: No. of Drawings | C8: Submitted (On This Month) | D8: Total Submitted | E8: Approved | F8: Rejected | G8: Under Review | H8: Balance to Submit | I8: Remarks
A9: Electrical | B9: 190 | C9: 0 | D9: =+E9+F9+G9 -> 190 | E9: =+B9 -> 190 | F9: 0 | G9: 0 | H9: =+B9-D9 -> 0
A10: HVAC | B10: 39 | C10: 0 | D10: =+E10+F10+G10 -> 39 | E10: =+B10 -> 39 | F10: 0 | G10: 0 | H10: =+B10-D10 -> 0
A11: Plumbing | B11: 97 | C11: 0 | D11: =+E11+F11+G11 -> 97 | E11: =+B11 -> 97 | F11: 0 | G11: 0 | H11: =+B11-D11 -> 0
A12: Fire Fighting | B12: 34 | C12: 0 | D12: =+E12+F12+G12 -> 34 | E12: =+B12 -> 34 | F12: 0 | G12: 0 | H12: =+B12-D12 -> 0
A13: Builders work | B13: 25 | C13: 0 | D13: =+E13+F13+G13 -> 25 | E13: =+B13 -> 25 | F13: 0 | G13: 0 | H13: =+B13-D13 -> 0
A14: Coordination | B14: 42 | C14: 0 | D14: =+E14+F14+G14 -> 42 | E14: =+B14 -> 42 | F14: 0 | G14: 0 | H14: =+B14-D14 -> 0
A15: BMS | B15: 35 | C15: 0 | D15: =+E15+F15+G15 -> 35 | E15: =+B15 -> 35 | F15: 0 | G15: 0 | H15: =+B15-D15 -> 0
A16: External | B16: 52 | C16: 0 | D16: =+E16+F16+G16 -> 52 | E16: =+B16 -> 52 | F16: 0 | G16: 0 | H16: =+B16-D16 -> 0
A20: Total | B20: =SUM(B9:B19) -> 514 | C20: =SUM(C9:C19) -> 0 | D20: =SUM(D9:D19) -> 514 | E20: =SUM(E9:E19) -> 514 | F20: =SUM(F9:F19) -> 0 | G20: =SUM(G9:G19) -> 0 | H20: =SUM(H9:H19) -> 0 | L20: =+E20/B20 -> 1
A22: Technical Queries ( TQ/ SCR/ RFC)
A24: Description | B24: Submitted | E24: Answered / Close | H24: Open
A25: Mechanical | B25: 0 | E25: 0 | H25: 0
A26: Electrical | B26: 0 | E26: 0 | H26: =B26-E26 -> 0
A27: Total | B27: =SUM(B25:D26) -> 0 | E27: =SUM(E25:G26) -> 0 | H27: =SUM(H25:I26) -> 0
A29: Open TQ's
A31: Description | B31: Sl No. | C31: Ref. No. | E31: Description | I31: Status
A32: Mechanical
A34: Electrical

Sheet 4-Procurement
G1: R67-M1-15 - Monthly Project Report PROCUREMENT | AR1: Doc. No.: | AV1: REE/OPR/05.3
AR2: Rev.: | AV2: 0
AR3: Date.: | AV3: =+'Cover '!T11 -> 42460
A5: As of: | F5: =AV3 -> 42460
A7: Material Submittal
A9: Description | K9: No. of Submittal | R9: Planned Submission (On This Month) | Y9: Actual Submitted | AF9: Approved | AM9: Rejected | AT9: Under Review | BA9: Balance to Submit
A10: HVAC | K10: 23 | R10: 0 | Y10: 23 | AF10: 23 | AM10: 0 | AT10: 0 | BA10: =K10-AF10+AM10 -> 0
A11: Plumbing | K11: 31 | R11: 0 | Y11: 31 | AF11: 31 | AM11: 0 | AT11: 0 | BA11: =K11-AF11+AM11 -> 0
A12: Fire Fighting | K12: 25 | R12: 0 | Y12: 25 | AF12: 25 | AM12: 0 | AT12: 0 | BA12: 0
A13: Electrical | K13: 29 | R13: 0 | Y13: 29 | AF13: 29 | AM13: 0 | AT13: 0 | BA13: 0
A15: Total | K15: =SUM(K10:Q14) -> 108 | R15: =SUM(R10:X14) -> 0 | Y15: =SUM(Y10:AE14) -> 108 | AF15: =SUM(AF10:AL14) -> 108 | AM15: =SUM(AM10:AS14) -> 0 | AT15: =SUM(AT10:AZ14) -> 0 | BA15: =SUM(BA10:BG14) -> 0
A17: Material Purchase Order - Long Lead
A19: Description | K19: No. of PO upto Last Month (Up to Jan-16) | T19: Plan PO to be issued This Month (Feb-16) | AD19: MR Released This month (Feb-16) | AN19: Actual - PO issued This Month (Feb-16) | AX19: Remaining POs This Month
A20: HVAC | K20: 23 | T20: 0 | AD20: 0 | AN20: 0 | AX20: 0
A21: Plumbing | K21: 31 | T21: 0 | AD21: 0 | AN21: 0 | AX21: 0
A22: Fire Fighting | K22: 25 | T22: 0 | AD22: 0 | AN22: 0 | AX22: 0
A23: Electrical | K23: 29 | T23: 0 | AD23: 0 | AN23: 0 | AX23: 0
A24: Others | K24: 1 | T24: 0 | AD24: 0 | AN24: 0 | AX24: 0
A25: Total | K25: =SUM(K20:S24) -> 109 | T25: =SUM(T20:AC24) -> 0 | AD25: =SUM(AD20:AM24) -> 0 | AN25: =SUM(AN20:AW24) -> 0 | AX25: =SUM(AX20:BG24) -> 0

Sheet 4.1-Logs
G1: R67-M1-15 - Monthly Project Report PROCUREMENT | AR1: Doc. No.: | AV1: REE/OPR/05.3
AR2: Rev.: | AV2: 0
AR3: Date.: | AV3: =+'Cover '!T11 -> 42460
F5: =AV3 -> 42460

Sheet 4.2-Long Lead Tracking
C1: R67-M1-15 - Monthly Project Report PROCUREMENT | L1: Doc. No.: | M1: REE/OPR/05.3.2
L2: Rev.: | M2: 0
L3: Date: | M3: =+'Cover '!T11 -> 42460
A5: Long Lead Material Track Sheet (Delivery Period more than 8 Weeks)
A7: S.No | B7: Item Description | D7: Required at Site | E7: Material Approval Status | F7: MR Date | G7: PO release Date | H7: Delivery | K7: Material Inspection | L7: Installation @ Site | M7: Remarks
H8: Deliver Period | I8: Confirm by Sup | J8: Actual
A9: 1 | B9: Air Handling Units (AHU's) | D9: 42309 | E9: Approved | F9: 42261 | G9: 42264 | H9: 60 | I9: 81 | J9: 83 | K9: Done | L9: Done | M9: Delivered
A10: =A9+1 -> 2 | B10: Air Terminals | D10: 42257 | E10: Approved | F10: 42241 | G10: 42248 | H10: 50 | I10: 75 | J10: 121 | K10: Done | L10: In Progress | M10: Delivered
A11: =A10+1 -> 3 | B11: VRF Units | D11: 42292 | E11: Approved | F11: 42227 | G11: 42231 | H11: 45 | I11: 61 | J11: 75 | K11: Done | L11: Done | M11: Delivered
A12: =A11+1 -> 4 | B12: Fans | D12: 42267 | E12: Approved | F12: 42143 | G12: 42227 | H12: 80 | I12: 80 | J12: 95 | K12: Done | L12: Done | M12: Delivered
A13: =A12+1 -> 5 | B13: DX-Split Unit | D13: 42292 | E13: Approved | F13: 42227 | G13: 42231 | H13: 45 | I13: 61 | J13: 65 | K13: Done | L13: Done | M13: Delivered
A14: =A13+1 -> 6 | B14: Water Filters | D14: 42257 | E14: Approved | F14: 42147 | G14: 42215 | H14: 90 | I14: 112 | J14: 120 | K14: Done | L14: Done | M14: Delivered
A15: =A14+1 -> 7 | B15: Water Heaters | D15: 42257 | E15: Approved | F15: 42147 | G15: 42148 | H15: 90 | I15: 112 | J15: 145 | K15: Done | L15: Done | M15: Delivered
A16: =A15+1 -> 8 | B16: Booster Pumps | D16: 42257 | E16: Approved | F16: 42224 | G16: 42225 | H16: 30 | I16: 30 | J16: 35 | K16: Done | L16: Done | M16: Delivered
A17: =A16+1 -> 9 | B17: Sump Pumps | D17: 42257 | E17: Approved | F17: 42253 | G17: 42261 | H17: 60 | I17: 30 | J17: 35 | K17: Done | L17: Done | M17: Delivered
A18: =A17+1 -> 10 | B18: Hot Water Circulation Pumps | D18: 42257 | E18: Approved | F18: 42141 | G18: 42143 | H18: 100 | I18: 115 | J18: 105 | K18: Done | L18: Done | M18: Delivered
A19: =A18+1 -> 11 | B19: Water Cooler | D19: 42280 | E19: Approved | F19: 42221 | G19: 42225 | H19: 50 | I19: 60 | J19: 75 | K19: Done | L19: Done | M19: Delivered
A20: =A19+1 -> 12 | B20: Oil/Grease Intercepter | D20: 42280 | E20: Approved | F20: 42157 | G20: 42158 | H20: 90 | I20: 90 | J20: 104 | K20: Done | L20: Done | M20: Delivered
A21: =A20+1 -> 13 | B21: FM 200 System | D21: 42318 | E21: Approved | F21: 42189 | G21: 42193 | H21: 90 | I21: 90 | J21: 125 | K21: Done | L21: Done | M21: Delivered
A22: =A21+1 -> 14 | B22: Foam Fire Supression System | D22: 42318 | E22: Approved | F22: 42189 | G22: 42193 | H22: 90 | I22: 90 | J22: 125 | K22: Done | L22: Done | M22: Delivered
A23: 15 | B23: Fire Hose Reel & Cabinet | D23: 42248 | E23: Approved | F23: 42189 | G23: 42193 | H23: 90 | I23: 90 | J23: 115 | K23: Done | L23: Done | M23: Delivered
A24: 16 | B24: Firefighting Pump | D24: 42292 | E24: Approved | F24: 42189 | G24: 42193 | H24: 120 | I24: 120 | J24: 160 | K24: Done | L24: Done | M24: Delivered
A25: 17 | B25: Aerosol Fire Supression System | D25: 42318 | E25: Approved | F25: 42189 | G25: 42193 | H25: 90 | I25: 90 | J25: 115 | K25: Done | L25: Done | M25: Delivered
A26: 18 | B26: Generator | D26: 42287 | E26: Approved | F26: 42220 | G26: 42226 | H26: 60 | I26: 60 | J26: 68 | K26: Done | L26: Done | M26: Delivered
A27: 19 | B27: Transformer | D27: 42262 | E27: Approved | F27: 42145 | G27: 42147 | H27: 90 | I27: 90 | J27: 104 | K27: Done | L27: Done | M27: Delivered
A28: 20 | B28: Power Cables | D28: 42219 | E28: Approved | F28: 42234 | G28: 42239 | H28: 45 | I28: 45 | J28: 65 | K28: Done | L28: Done | M28: Delivered
A29: 21 | B29: CBS Equipment | D29: 42322 | E29: Approved | F29: 42240 | G29: 42241 | H29: 80 | I29: 80 | J29: 138 | K29: Done | L29: In Progress | M29: Delivered
A30: 22 | B30: DB's | D30: 42282 | E30: Approved | F30: 42177 | G30: 42219 | H30: 45 | I30: 45 | J30: 65 | K30: Done | L30: In Progress | M30: Delivered
A31: 23 | B31: MCC Panels | D31: 42282 | E31: Rejected | F31: 42177 | G31: 42303 | H31: 25 | I31: 25 | J31: 94 | K31: Done | L31: Done | M31: Delivered
A32: 24 | B32: SMDB's | D32: 42282 | E32: Approved | F32: 42177 | G32: 42219 | H32: 45 | I32: 45 | J32: 65 | K32: Done | L32: Done | M32: Delivered
A33: 25 | B33: Capacitor Bank | D33: 42282 | E33: Approved | F33: 42177 | G33: 42219 | H33: 45 | I33: 45 | J33: 65 | K33: Done | L33: Done | M33: Delivered
A34: 26 | B34: LV Panels | D34: 42282 | E34: Approved | F34: 42184 | G34: 42219 | H34: 45 | I34: 45 | J34: 65 | K34: Done | L34: Done | M34: Delivered

Sheet 5-QA-QC
F1: R67-M1-15 - Monthly Project Report QA/QC | AR1: Doc. No.: | AV1: REE/OPR/05.4
AR2: Rev.: | AV2: 0 | AW2: 0
AR3: Date: | AV3: =+'Cover '!T11 -> 42460
A5: As of: | F5: =AV3 -> 42460
A7: Material Inspection
A9: Description | K9: Total | W9: Approved | AI9: Rejected | AU9: Open
A10: HVAC | K10: 30 | W10: =+K10 -> 30 | AI10: 0 | AU10: 0
A11: Plumbing
A12: Fire Fighting
A13: Electrical | K13: 27 | W13: =+K13 -> 27 | AI13: 0 | AU13: 0
A14: Total | K14: =SUM(K10:V13) -> 57 | W14: =SUM(W10:AH13) -> 57 | AI14: =SUM(AI10:AT13) -> 0 | AU14: =SUM(AU10:BF13) -> 0
A16: Installation Inspection
A18: Description | K18: Total | W18: Approved | AI18: Rejected | AU18: Open
A19: HVAC | K19: 608 | W19: 344 | AI19: 221 | AU19: 43
A20: Plumbing
A21: Fire Fighting
A22: Electrical | K22: 523 | W22: 328 | AI22: 186 | AU22: 9
A23: Total | K23: =SUM(K19:V22) -> 1131 | W23: =SUM(W19:AH22) -> 672 | AI23: =SUM(AI19:AT22) -> 407 | AU23: =SUM(AU19:BF22) -> 52
A25: NCR- Non Conformance Report
A27: Description | K27: Total - Received | AA27: Closed | AQ27: Open
A28: External | K28: 29 | AA28: 11 | AQ28: =K28-AA28 -> 18
A29: Internal | K29: 0 | AA29: 0 | AQ29: =K29-AA29 -> 0
A30: Total | K30: =SUM(K28:Z29) -> 29 | AA30: =SUM(AA28:AP29) -> 11 | AQ30: =SUM(AQ28:BF29) -> 18
A32: Open NCR Details:
A34: Sl NO. | D34: Description | AQ34: Status
A35: 1 | D35: It has been noticed that installations of HVAC duct and pipes supports are done with an unapproved anchot bolt (unifix) in Chalets, Main Kitchen and Garage Building (Photos attached for your reference. You are hereby instructed to immediately stop the fixation of the mentioned works using the unacceptable material and replace it with the approved (Hilti) material. The contractor will bear all the contractual consequences in case he continue the works without the approved material and the contractual clauses will be applied in this case. | AQ35: Open
A36: 2 | D36: It was noticed that contractor is using rejected material for water supply system instead of approved materials "MUELLER" You are hreby instructed to replaced executed works with approved materials you are immediate corrective action is required. | AQ36: Open
A37: 3 | D37: Contractor is proceeding with external sewage network without approved IFC drawings & with unapproved material. | AQ37: Open
A38: 4 | D38: It was noticed that the contractor proceed the work (Floor Concrete) In Palace G.F. (Part # 03) Before inspection of Electrical works (Floor conduits) | AQ38: Open
A39: 5 | D39: Contractor is proceeding with works related to external drainage without submitting wor inspection request for manhole works for external drainage. | AQ39: Open
A40: 6 | D40: Contractor is proceeding with works related to external drainage without submitting wor inspection request for manhole works for external drainage. | AQ40: Open
A41: 7 | D41: UPVC piping infront of Staff Quarter have already concreted without the approved installation inspection and without rectifying the slope which is not accepted | AQ41: Open
A42: 8 | D42: With reference NCR 21, 29, & 31 Contractor is proceeding with works related to external Drainage drainage woithput approved work inspectio0nrequest for manhole & Sewage Networks for External Drainage. | AQ42: Open
A43: 9 | D43: 1. Spacing between Electrical PVC conduit pipes & Mechanical water pipes are not as per standard and regulation (Conduits in touch with water line) 2. Spacing between backwash pipes and power sleeves is must and either of them must be closed 3. Slab on Grade done without raising inspection request in Kitchen & Garage area | AQ43: Open
A44: 10 | D44: Backwash UPVC pipe line and water supply HDPE for pump room were backfilled and concreted before the time of inspection | AQ44: Open
A45: 11 | D45: UPVC Piping infront of Palace which is already inspected and backfilled, have been exposed due to some excavation in the area, resulting that the pipes are exposed and bended which will affect the drainage systems | AQ45: Open
A46: 12 | D46: Copper tape for lightening protection is casted in concrete prior to our inspection for installation (photo attached). Earth wire has been used for connection between two copper tape lenghts (phot attached). | AQ46: Open
... A52: 18 | D52: Using Improper fittings for back wash line in chalet 2 | AQ52: Open

Sheet 6-Construction
C1: R67-M1-15 - Monthly Project Report CONSTRUCTION | F1: Doc. No.: | G1: REE/OPR/05.5
F2: Rev.: | G2: 0
F3: Date: | G3: =+'Cover '!T11 -> 42460
A5: Progress Accomplished This Month (Major Activities only)
A7: S.No | B7: Activity Description | F7: Remarks
A8: 1 | B8: Testing & Commissioning of Fire fighting system in progress.
A9: 2 | B9: Pretesting of HVAC Equipment in progress
A10: 3 | B10: Testing & Commissioning of Electrical Equipment in progress
A11: 4 | B11: Pretesting of panels in progress.
A12: 5 | B12: Installation of Wiring Devices & Light Fixture in Palace & Chalets.
A13: 6 | B13: Isolator Installation & termination for equipment in progress
A14: 7 | B14: Sanitary ware installation in chalet & palace in progress
A15: 8 | B15: Grills & Diffuser Installation in palace in progress parallel with civil.
A24: One Month Look Ahead Plan (Major Activities only)
A26: S.No | B26: Activity Description | D26: Tentative Start Date | F26: Remarks
A27: 1 | B27: Final Testing & Commissioning | D27: 42478
A28: 2 | B28: Project Close Out | D28: 42484

Sheet 7-Project Scope +Revenue Detail
B1: R67-M1-15 - Monthly Project Report COMMERICAL | H1: Doc. No. | I1: REE/OPR/05.6
H2: Rev.: | I2: 1
H3: Date: | I3: =+'Cover '!T11 -> 42460
A5: Project Scope Value Details
A7: Current Scope Value | D7: VO Breakdown | G7: Expected Contract Value
A8: Original Contract Value | C8: 49200000 | D8: Submitted | F8: ='7.2-Scope Management'!G18 -> 3614250.7 | G8: Current Scope Value | H8: =A15 -> 52051339
A9: Revised / Adjustment B O Q | C9: 0 | D9: Approved | F9: =+C10 -> 154913.84 | G9: Exp. Re-measured Qty | H9: 0
A10: Approved VO | C10: =+'7.2-Scope Management'!C21 -> 154913.84 | D10: Rejected / Cancalled | F10: =+'7.2-Scope Management'!C23 -> 762911.73 | G10: Not- Approved Variations | H10: 0
A11: Scope Deletion | C11: 0 | D11: Under Revise | F11: - | G11: EOT- (Submitted) | H11: 0
A12: Not Approved Under Execution | C12: =+'7.2-Scope Management'!C22 -> 2696425.1 | D12: Not Approved, Under Execution | F12: =+'7.2-Scope Management'!C22 -> 2696425.1 | G12: Expected New Variations | H12: 0
A13: Additonal QTY | C13: 0 | G13: Domestic Claim | H13: 0
A15: =SUM(C8:C14) -> 52051339 | D15: =SUM(F9:F12) -> 3614250.7 | G15: =SUM(H8:I13) -> 52051339
A17: Project Revenue Details
C18: Previous | E18: Current | H18: Forecast
C19: 42429 | E19: 42460 | H19: =E19+28 -> 42488
A20: Plan | B20: Monthly | C20: =2.55%*49200000 -> 1254600 | E20: =C10 -> 154913.84 | H20: =H21-E21 -> 2696425.1
B21: Camulative | C21: =+'2-Schedule'!Z22*'7-Project Scope +Revenue Detail'!C8 -> 49200000 | E21: =C21+E20 -> 49354914 | H21: =A15 -> 52051339
A22: Actual | B22: Monthly | C22: =+'7.1-Payment-Detail'!D16 -> 2459235.9 | E22: =+'7.1-Payment-Detail'!C17 -> 3416480.8
B23: Camulative | C23: ='7.1-Payment-Detail'!D19 -> 40992024 | E23: =C23+E22 -> 44408504
A24: Variance | B24: Monthly | C24: =C22-C20 -> 1204635.9 | E24: =E22-E20 -> 3261567
B25: Camulative | C25: =C23-C21 -> -8207976.4 | E25: =E23-E21 -> -4946409.4
D33: =E23/C8 -> 0.90261188

Sheet 7.1-Payment-Detail
B1: R67-M1-15 - Monthly Project Report COMMERICAL | F1: Doc. No. | G1: REE/OPR/05.6
F2: Rev.: | G2: 0
F3: Date: | G3: =+'Cover '!T11 -> 42460
A5: Payment Application Details
A7: Payment Application Details | D7: Certification Details | F7: Outstanding Amount
A8: Application No | B8: Application Month | C8: Gross Application Amount | D8: Certified Amount | E8: Back Charges
A9: Application # 01 | B9: 42156 | C9: 2996167.9 | D9: 1938041.3 | E9: 0 | F9: =D9-E9 -> 1938041.3
A10: Application # 02 | B10: 42217 | C10: 5186175.7 | D10: 5202842.4 | E10: 0 | F10: =D10-E10 -> 5202842.4
A11: Application # 03 | B11: 42248 | C11: 7538395.7 | D11: 7538395.7 | E11: 0 | F11: =D11-E11 -> 7538395.7
A12: Application # 04 | B12: 42278 | C12: 4743047.6 | D12: 4743047.6 | E12: 717523.49 | F12: =D12-E12 -> 4025524.1
A13: Application # 05 | B13: 42309 | C13: 16848141 | D13: 12499873 | E13: 0 | F13: =D13-E13 -> 12499873
A14: Application # 06 | B14: 42339 | C14: 6292070.9 | D14: 2965648.9 | E14: 1174841.3 | F14: =D14-E14 -> 1790807.6
A15: Application # 07 | B15: 42370 | C15: 5597711.2 | D15: 3644939 | E15: 535277.25 | F15: =D15-E15 -> 3109661.8
A16: Application # 08 | B16: 42401 | C16: 3687342 | D16: 2459235.9
A17: Application # 09 | B17: 42430 | C17: 3416480.8
A19: G. Total: | C19: =C17+D19 -> 44408504 | D19: =SUM(D9:D18) -> 40992024 | E19: =SUM(E9:E18) -> 2427642 | F19: =SUM(F9:G18) -> 36105146

Sheet 7.2-Scope Management
B1: R67-M1-15 - Monthly Project Report COMMERCIAL | M1: Doc No.: | N1: REE/OPR/05.6
M2: Rev.: | N2: 0
M3: Date: | N3: =+'Cover '!T11 -> 42460
A5: Scope Management Matrix
A7: VO # / Client Ref. | B7: Description | C7: VO Value Breakdown (Acual Cost) | G7: Value of VO | K7: Current Status (%) | N7: Remarks
C8: Material | D8: Manpower | E8: Indirect Cost | F8: O/H, M-Res + Profit | G8: Submitted | H8: Agreed | I8: Approved | J8: Status | K8: Progress | L8: Claim | M8: Certification
A9: VO.1 | B9: Modification of FM200 System in Main Gate. | C9: 39738.436 | D9: 13246.145 | E9: 3311.5363 | F9: 9934.609 | G9: =SUM(C9:F9) -> 66230.727 | H9: 48481.3 | J9: Agreed | N9: Action Required By UCC | P9: =H9 -> 48481.3 | Q9: =P9/G9 -> 0.73200616 | R9: =$Q$9*C9 -> 29088.78 | S9: =$Q$9*D9 -> 9696.26 | T9: =$Q$9*E9 -> 2424.065 | U9: =$Q$9*F9 -> 7272.195
A10: VO.2 Rev.01 | B10: Additional Swimming Pool Filling Line, Pumps & Backwash system. | C10: 103099.38 | D10: 43354.364 | E10: 12569.806 | F10: 23981.238 | G10: =SUM(C10:F10) -> 183004.79 | I10: 128037.44 | J10: Approved | N10: - | P10: =I10 -> 128037.44 | Q10: =P10/G10 -> 0.69963983 | R10: =$Q$10*C10 -> 72132.433 | S10: =$Q$10*D10 -> 30332.44 | T10: =$Q$10*E10 -> 8794.3372 | U10: =$Q$10*F10 -> 16778.23
A11: VO.3 Rev.01 | B11: Additional VAV System & Related BMS Items | C11: 12847.203 | D11: 7208.7617 | E11: 5647.8965 | F11: 3591.4143 | G11: =SUM(C11:F11) -> 29295.276 | I11: 26876.4 | J11: Approved | N11: - | P11: =I11 -> 26876.4 | Q11: =P11/G11 -> 0.91743119 | R11: =$Q11*C11 -> 11786.425 | S11: =$Q11*D11 -> 6613.5429 | T11: =$Q11*E11 -> 5181.5564 | U11: =$Q11*F11 -> 3294.8755
A12: VO.4 | B12: Additional Centarl Battery System | C12: 418245.15 | D12: 127374.29 | E12: 29177.674 | F12: 56620.834 | G12: =SUM(C12:F12) -> 631417.95 | H12: 450000 | J12: Agreed | N12: Action Required By UCC | P12: =H12 -> 450000 | Q12: =P12/G12 -> 0.71268167 | R12: =$Q12*C12 -> 298075.65 | S12: =$Q12*D12 -> 90777.324 | T12: =$Q12*E12 -> 20794.393 | U12: =$Q12*F12 -> 40352.63
A13: VO.5 | B13: Additional Shoower Grating, Pipe Workd & Floor Drain | C13: 48399.315 | D13: 5052.5792 | E13: 2780.7554 | F13: 5453.3501 | G13: =SUM(C13:F13) -> 61686 | H13: 49000 | J13: Agreed | N13: Action Required By UCC | P13: =H13 -> 49000 | Q13: =P13/G13 -> 0.79434556 | R13: =$Q13*C13 -> 38445.781 | S13: =$Q13*D13 -> 4013.4938 | T13: =$Q13*E13 -> 2208.8807 | U13: =$Q13*F13 -> 4331.8444
A14: VO.6 | B14: Additional External Containment for ELV Cables | C14: 145281.07 | D14: 291410.16 | E14: 26221.035 | F14: 48055.596 | G14: =SUM(C14:F14) -> 510967.86 | H14: 426109.82 | J14: Agreed | N14: Action Required By UCC | P14: =H14 -> 426109.82 | Q14: =P14/G14 -> 0.83392685 | R14: =$Q14*C14 -> 121153.78 | S14: =$Q14*D14 -> 243014.76 | T14: =$Q14*E14 -> 21866.425 | U14: =$Q14*F14 -> 40074.852
A15: VO.7 | B15: Additional DBs, SMDBs With Feeder Cable & Cable Containment | C15: 225897.68 | D15: 58994.43 | E15: 44129.637 | F15: 29056.335 | G15: =SUM(C15:F15) -> 358078.08 | H15: 270538 | J15: Agreed | N15: Action Required By UCC | P15: =H15 -> 270538 | Q15: =P15/G15 -> 0.75552795 | R15: =$Q15*C15 -> 170672.01 | S15: =$Q15*D15 -> 44571.941 | T15: =$Q15*E15 -> 33341.174 | U15: =$Q15*F15 -> 21952.873
A16: VO.8 | B16: Additional Lighting For External Area | C16: 466229.9 | D16: 1071037.4 | E16: 156583.06 | F16: 79719.693 | G16: =SUM(C16:F16) -> 1773570 | H16: 1452296 | J16: Agreed | N16: Action Required By UCC | P16: =H16 -> 1452296 | Q16: =P16/G16 -> 0.81885463 | R16: =$Q16*C16 -> 381774.51 | S16: =$Q16*D16 -> 877023.89 | T16: =$Q16*E16 -> 128218.76 | U16: =$Q16*F16 -> 65278.84
A18: Total: | C18: =SUM(C9:C17) -> 1459738.1 | D18: =SUM(D9:D17) -> 1617678.1 | E18: =SUM(E9:E17) -> 280421.4 | F18: =SUM(F9:F17) -> 256413.07 | G18: =SUM(G9:G17) -> 3614250.7 | H18: =SUM(H9:H17) -> 2696425.1 | I18: =SUM(I9:I17) -> 154913.84 | R18: =C16/H16 -> 0.32102953
B20: V.O clasifications | C20: Value
B21: Approved Variation orders (by client) | C21: =I18 -> 154913.84
B22: Variation orders that already agreed by UCC - Work already executed at site | C22: =H18 -> 2696425.1
B23: Cancelled and / or rejected Variation orders | C23: =+G18-(C22+C21) -> 762911.73
B24: Variation orders that still under review by Client and work not yet executed | C24: 0
B25: Total Value of the Variation orders | C25: =SUM(C21:C24) -> 3614250.7
D28: Executed, Approved & Agreed
D30: Material | E30: Manpower | F30: Indirect Cost | G30: O/H, M-Res + Profit
C32: VO.1 | D32: =R9 -> 29088.78 | E32: =S9 -> 9696.26 | F32: =T9 -> 2424.065 | G32: =U9 -> 7272.195 | H32: =SUM(D32:G32) -> 48481.3
C33: VO.2 | D33: =R10 -> 72132.433 | E33: =S10 -> 30332.44 | F33: =T10 -> 8794.3372 | G33: =U10 -> 16778.23 | H33: =SUM(D33:G33) -> 128037.44
C34: VO.3 | D34: =R11 -> 11786.425 | E34: =S11 -> 6613.5429 | F34: =T11 -> 5181.5564 | G34: =U11 -> 3294.8755 | H34: =SUM(D34:G34) -> 26876.4
C35: VO.4 | D35: =R12 -> 298075.65 | E35: =S12 -> 90777.324 | F35: =T12 -> 20794.393 | G35: =U12 -> 40352.63 | H35: =SUM(D35:G35) -> 450000
C36: VO.5 | D36: =R13 -> 38445.781 | E36: =S13 -> 4013.4938 | F36: =T13 -> 2208.8807 | G36: =U13 -> 4331.8444 | H36: =SUM(D36:G36) -> 49000
C37: VO.6 | D37: =R14 -> 121153.78 | E37: =S14 -> 243014.76 | F37: =T14 -> 21866.425 | G37: =U14 -> 40074.852 | H37: =SUM(D37:G37) -> 426109.82
C38: VO.7 | D38: =R15 -> 170672.01 | E38: =S15 -> 44571.941 | F38: =T15 -> 33341.174 | G38: =U15 -> 21952.873 | H38: =SUM(D38:G38) -> 270538
C39: VO.8 | D39: =R16 -> 381774.51 | E39: =S16 -> 877023.89 | F39: =T16 -> 128218.76 | G39: =U16 -> 65278.84 | H39: =SUM(D39:G39) -> 1452296
D42: =SUM(D32:D41) -> 1123129.4 | E42: =SUM(E32:E41) -> 1306043.7 | F42: =SUM(F32:F41) -> 222829.59 | G42: =SUM(G32:G41) -> 199336.34 | H42: =SUM(D42:G42) -> 2851339
D45: Executed & Submitted
H47: =SUM(D47:G47) -> 0
H48: =SUM(D48:G48) -> 0
H49: =SUM(D49:G49) -> 0
H50: =SUM(D50:G50) -> 0
D55: =SUM(D47:D54) -> 0 | E55: =SUM(E47:E54) -> 0 | F55: =SUM(F47:F54) -> 0 | G55: =SUM(G47:G54) -> 0 | H55: =SUM(D55:G55) -> 0
D58: =+D55+D42 -> 1123129.4 | E58: =+E55+E42 -> 1306043.7 | F58: =+F55+F42 -> 222829.59 | G58: =+G55+G42 -> 199336.34 | H58: =SUM(D58:G58) -> 2851339

Sheet 7.3-sub-con
I1: R67-M1-15 - Monthly Project Report CONSTRUCTION | BG1: Doc. No.: | BM1: REE/OPR/05.5
BG2: Rev.: | BM2: 0
BG3: Date: | BM3: =+'Cover '!T11 -> 42460
A5: Sub Contractor- 1 Status
A6: SubCon Name: | M6: Consolidated Engineering System CO. W.L.L | AT6: Scope: | BA6: Fire Fighting
A7: Sub-Contract Value | T7: Approved VO | AM7: Total Scope Value | BG7: Claim | BR7: Certified as of
A8: 608040 | T8: 302409.24 | AM8: =A8+T8 -> 910449.24 | BG8: 710614.3 | BR8: 685096.99
A9: Progress | J9: Engineering | T9: Manpower | AC9: Material | AM9: Long Lead Items | AW9: Progress | BG9: Inspection | BP9: Claim by MEP (%)
A10: Plan | J10: 12 | T10: 5 | AC10: 19 | AM10: 5 | AW10: 1
A11: Actual | J11: 12 | T11: 3 | AC11: 19 | AM11: 5 | AW11: 0.95
A12: Variance | J12: 0 | T12: =T11-T10 -> -2 | AC12: 0 | AM12: 0 | AW12: =AW11-AW10 -> -0.05
A13: Remarks
A14: Sub Contractor- 2 Status
A15: SubCon Name: | M15: Al Mana Networks Solutions & Security Services | AT15: Scope: | BA15: BMS
A16: Sub-Contract Value | T16: Approved VO | AM16: Total Scope Value | BG16: Claim | BR16: Certified as of
A17: 620000 | AM17: =A17+T17 -> 620000 | BG17: 620314.93 | BR17: 558018.52
A18: Progress | J18: Engineering | T18: Manpower | AC18: Material | AM18: Long Lead Items | AW18: Progress | BG18: Inspection | BP18: Claim by MEP (%)
A19: Plan | J19: 32 | T19: 7 | AC19: 2 | AM19: 1 | AW19: 1
A20: Actual | J20: 32 | T20: 5 | AC20: 2 | AM20: 1 | AW20: 0.88
A21: Variance | J21: 0 | T21: -2 | AC21: 0 | AM21: 0 | AW21: =AW20-AW19 -> -0.12
A22: Remarks
A24: Sub Contractor- 3 Status
A25: SubCon Name: | M25: Asian Insulation Co. | AT25: Scope: | BA25: Aluminium Clading on External Duct Work
A26: Sub-Contract Value | T26: Approved VO | AM26: Total Scope Value | BG26: Claim | BR26: Certified as of
A27: 424800 | AM27: =A27+T27 -> 424800 | BG27: 349973.94 | BR27: 286253.94
A28: Progress | J28: Engineering | T28: Manpower | AC28: Material | AM28: Long Lead Items | AW28: Progress | BG28: Inspection | BP28: Claim by MEP (%)
A29: Plan | J29: N/A | T29: 9 | AC29: 1 | AM29: 1 | AW29: 0.75
A30: Actual | J30: N/A | T30: 5 | AC30: 1 | AM30: 1 | AW30: =+BR27/AM27 -> 0.67385579
A31: Variance | J31: N/A | T31: =T30-T29 -> -4 | AC31: 0 | AM31: 0 | AW31: =AW30-AW29 -> -0.076144209
A32: Remarks
A33: Sub Contractor- 4 Status
A34: SubCon Name: | M34: Al Marshal Trading & Contracting | AT34: Scope: | BA34: Cable Pulling & PVC Sleeve Pipe Istallation
A35: Sub-Contract Value | T35: Approved VO | AM35: Total Scope Value | BG35: Claim | BR35: Certified as of
A36: OPEN | AM36: OPEN | BG36: 701691 | BR36: 701691
A37: Progress | J37: Engineering | T37: Manpower | AC37: Material | AM37: Long Lead Items | AW37: Progress | BG37: Inspection | BP37: Claim by MEP (%)
A38: Plan | J38: N/A | T38: 21 | AC38: N/A | AM38: N/A | AW38: 1
A39: Actual | J39: N/A | T39: 23 | AC39: N/A | AM39: N/A | AW39: 1
A40: Variance | J40: N/A | T40: 2 | AC40: N/A | AM40: N/A | AW40: 0
A41: Remarks | J41: Work Completed
A43: Sub Contractor- 5 Status
...

Sheet 7.4-Back Chargs detail
B1: R67-M1-15 - Monthly Project Report COMMERICAL | H1: Doc. No. | I1: REE/OPR/05.6
H2: Rev.: | I2: 0
H3: Date: | I3: =+'Cover '!T11 -> 42460
A5: Back Charges Details
A7: Back Charges Details | E7: MEP Acceptance on Back Charges | F7: Fair Amount for Back Charges | G7: Cost Code/ BOQ Section for Back charges | H7: Remarks
A8: Application No | B8: Application Month | C8: Back Charges Amount | D8: Back Charges for
A9: 4 | B9: 42278 | C9: 717523.49 | D9: Materials & Labour Supply | E9: 717523.49
A10: 6 | B10: 42339 | C10: 1174841.3 | D10: Materials, Staff & Labour Supply | E10: 1174841.3
A11: 7 | B11: 42400 | C11: 535277.25 | D11: LRD Labour Supply | E11: 535277.25
A18: G. Total: | C18: =SUM(C9:C17) -> 2427642 | E18: =SUM(E9:E17) -> 2427642 | F18: =SUM(F9:F17) -> 0 | G18: =SUM(G9:G17) -> 0 | H18: =SUM(H9:I17) -> 0

Sheet 8-HSE
G1: R67-M1-15 - Monthly Project Report HSE & PPE | AR1: Doc. No.: | AW1: REE/OPR/05.7
AR2: Rev.: | AT2: 0 | AW2: 0
AR3: Date: | AT3: 41922 | AW3: =+'Cover '!T11 -> 42460
A5: HSE Report
R7: Upto Last Month (Cumulative) | AG7: This Month | AU7: Total
A8: Total Number of Employees (Manmonth) | R8: 4644 | AG8: 165 | AU8: =AG8+R8 -> 4809
A9: Man-hours Worked | R9: 11380000 | AG9: 51440 | AU9: =R9+AG9 -> 11431440
A10: Man-hours Without LTI | R10: =R9 -> 11380000 | AG10: =AG9 -> 51440 | AU10: =R10+AG10 -> 11431440
A11: Man-hours Without LTA | R11: =R10 -> 11380000 | AG11: =AG9 -> 51440 | AU11: =R11+AG11 -> 11431440
A12: First Aid Case | R12: 39 | AG12: 3 | AU12: =R12+AG12 -> 42
A13: Major Injuries | R13: 0 | AG13: 0 | AU13: =R13+AG13 -> 0
A14: Medical Case | R14: 36 | AG14: 5 | AU14: =R14+AG14 -> 41
A15: Occupational Illness
A17: Incident Reports | O17: Near Miss | X17: Unsafe Act. | AI17: Unsafe Condition | AU17: Damage Report
A18: This Month | O18: 0 | X18: 1 | AI18: 1 | AU18: 0
A19: Last Month | O19: 1 | X19: 18 | AI19: 7 | AU19: 1
A21: Induction / Training | O21: HSE Induction | X21: In house Training | AI21: Tool Box Talks | AU21: Tool Box Topics
A22: This Month | O22: 0 | X22: 2 | AI22: 3 | AU22: Hot work - Work on live electrical equipment , LOTO - Confined Space
A23: Last Month | O23: 3 | X23: 1 | AI23: 7 | AU23: Electrical Safety -PPE , Manual Hand Work at Height
A25: PPE
L27: Safety Shoes | R27: Helmet | X27: Jacket | AD27: Cover | AJ27: Gloves | AP27: Goggles
A29: Issued This Month | L29: 0 | R29: 0 | X29: 0 | AD29: 0 | AJ29: 0 | AP29: 0
A30: Available In Store | L30: 20 | R30: 14 | X30: 23 | AD30: 0 | AJ30: 0 | AP30: 8
A31: New Requirement | L31: 0 | R31: 0 | X31: 0 | AD31: 0 | AJ31: 0 | AP31: 0
A32: Remarks

Sheet 9-Budget-Cost-ETC-EAC
B1: R67-M1-15 - Monthly Project Report Cost Control | G1: Doc. No. | H1: REE/OPR/05.8
G2: Rev.: | H2: 0
G3: Date: | H3: =+'Cover '!T11 -> 42460
A5: EARNED VALUE MANAGEMENT
A7: Description | C7: Budget | D7: Actual Cost | E7: ETC - Estimate To Complete Cost | F7: EAC - Estimate At Completion Cost | H7: Variances (Budget- EAC)
A8: Material Cost | B8: HVAC | C8: =7312048+(395000*0.3) -> 7430548 | D8: 8321542.6 | E8: 30000 | F8: =D8+E8 -> 8351542.6 | J8: =L8+N8 -> 8321542.6 | L8: =$N$15*0.3 -> 415170.84 | N8: 7906371.8
B9: Fire Fighting | C9: =3320091+(395000*0.1) -> 3359591 | D9: 3259443.5 | E9: 30000 | F9: =D9+E9 -> 3289443.5 | J9: =L9+O9 -> 3259443.5 | L9: =$N$15*0.1 -> 138390.28 | N9: 666791.84 | O9: =N9+N10 -> 3121053.2
B10: Plumbing | N10: 2454261.4
B11: Electrical | C11: =14803630+(395000*0.6) -> 15040630 | D11: 15086146 | E11: 200000 | F11: =D11+E11 -> 15286146 | J11: =L11+N11 -> 15086146 | L11: =$N$15*0.6 -> 830341.67 | N11: 14255804
B12: Variation Order | C12: =+'7.2-Scope Management'!D58 -> 1123129.4 | D12: 0 | E12: 0 | F12: =D12+E12 -> 0
B13: Total | C13: =SUM(C8:C12) -> 26953898 | D13: =SUM(D8:D12) -> 26667132 | E13: =SUM(E8:E12) -> 260000 | F13: =SUM(F8:G12) -> 26927132 | H13: =C13-F13 -> 26766.377 | J13: 1 4,217,600.26 | N13: 147900.07
A14: Manpower | B14: HVAC | C14: 6180000 | D14: 14217600 | E14: 514800 | F14: =D14+E14 -> 14732400 | N14: 1236002.7
B15: Fire Fighting | N15: =SUM(N13:N14) -> 1383902.8
B16: Plumbing
B17: Electrical
B18: Variation Order | C18: =+'7.2-Scope Management'!E58 -> 1306043.7
B19: Total | C19: =SUM(C14:C18) -> 7486043.7 | D19: =SUM(D14:D18) -> 14217600 | E19: =SUM(E14:E18) -> 514800 | F19: =SUM(F14:G18) -> 14732400 | H19: =C19-F19 -> -7246356.6 | J19: 3 ,172,453.77 | K19: 3172453.8
A20: Prelims (Staff/Misc) | C20: =4820000+1402000 -> 6222000 | D20: 3721391.3 | E20: 150000 | F20: =E20+D20 -> 3871391.3 | H20: =C20-F20 -> 2350608.7 | J20: 5 48,937.51 | K20: 548937.51
A21: Prelims - V. O. | C21: =+'7.2-Scope Management'!F58 -> 222829.59 | D21: 0 | E21: 0 | F21: =E21+D21 -> 0 | H21: =C21-F21 -> 222829.59 | K21: =SUM(K19:K20) -> 3721391.3
A22: Sub-Contract | C22: 2434887.3 | D22: 3315978.2 | E22: 150000 | F22: =D22+E22 -> 3465978.2
B25: Total | C25: =SUM(C22:C24) -> 2434887.3 | D25: =SUM(D22:D24) -> 3315978.2 | E25: =SUM(E22:E24) -> 150000 | F25: =SUM(F22:F24) -> 3465978.2 | H25: =C25-F25 -> -1031090.9 | J25: 3 ,315,978.16
A26: Other | B26: Scope Deletion | C26: 0 | D26: 0 | E26: 1000000 | F26: =D26+E26 -> 1000000
B27: Back Charges | C27: 0 | D27: 0 | E27: 0 | F27: =D27+E27 -> 0
B28: Total | C28: =SUM(C26:C27) -> 0 | D28: =SUM(D26:D27) -> 0 | E28: =SUM(E26:E27) -> 1000000 | F28: =SUM(F26:F27) -> 1000000 | H28: =C28-F28 -> -1000000
A29: G. Total: | C29: =C25+C21+C20+C19+C13+C28 -> 43319659 | D29: =D25+D21+D20+D19+D13+D28 -> 47922102 | E29: =E25+E21+E20+E19+E13+E28 -> 2074800 | F29: =F25+F21+F20+F19+F13+F28 -> 49996902 | H29: =C29-F29 -> -6677242.8
J30: =180*26*10*11 -> 514800
B31: Contract Value Including Vos | C31: Gross Profit (Budget) | E31: Gross Profit (EAC)
C32: Percentage % | D32: QR | E32: Percentage % | F32: QR
B33: =+'7-Project Scope +Revenue Detail'!A15 -> 52051339 | C33: =D33/B33 -> 0.16775131 | D33: =B33-C29 -> 8731680.1 | E33: =F33/B33 -> 0.039469441 | F33: =B33-F29 -> 2054437.3
A35: Note:
A36: 01. | B36: As of Our Record for the material recieved at site up to 31-Mar-16 | E36: 26163189
B37: Actual Material Cost as per Finance Report up to 31-Mar-16 | E37: =D13 -> 26667132
B38: Difference | E38: =E36-E37 -> -503942.72
A40: 02. | B40: Material Cost (EAC) - Exceeded with last month expected | E40: 3502161.9
B41: Sub Contract (EAC) - Exceeded with last month expected | E41: =F25-2884242.11 -> 581736.05

Sheet 10-Resources
G1: R67-M1-15 -Monthly Project Report RESOURCES | BD1: Doc. No.: | BI1: REE/OPR/05.9
BD2: Rev.: | BF2: 0 | BI2: 0
BD3: Date: | BF3: 41922 | BI3: =+'Cover '!T11 -> 42460
A6: Resources
L8: Manpower | AJ8: Man Hours | BH8: Mob / DE Mob Plan
L9: Cum. Last Month | R9: This Mionth | AJ9: Cum. Last Month | AP9: This Mionth
R10: Plan | X10: Actual | AD10: Variance | AP10: Plan | AV10: Actual | BB10: Variance | BH10: Mob | BN10: DE Mob
A11: Staff | L11: 347 | R11: 15 | X11: 10 | AD11: =X11-R11 -> -5 | AJ11: 72176 | AP11: =R11*10*26 -> 3900 | AV11: =X11*10*26 -> 2600 | BB11: =AV11-AP11 -> -1300 | BN11: 4
A12: Manpower | H12: HVAC | L12: ='8-HSE'!R8-L11 -> 4297 | R12: 16 | X12: 48 | AD12: =+R12-X12 -> -32 | AJ12: ='8-HSE'!R9-AJ11 -> 11307824 | AP12: =R12*10*26 -> 4160 | AV12: =X12*10*26 -> 12480 | BB12: =AV12-AP12 -> 8320 | BN12: 25
H13: FF | R13: 0 | X13: 3 | AD13: =+R13-X13 -> -3 | AP13: =R13*10*26 -> 0 | AV13: =X13*10*26 -> 780 | BB13: =AV13-AP13 -> 780 | BN13: 0
H14: PL | R14: 11 | X14: 24 | AD14: =+R14-X14 -> -13 | AP14: =R14*10*26 -> 2860 | AV14: =X14*10*26 -> 6240 | BB14: =AV14-AP14 -> 3380 | BN14: 10
H15: Elect. | R15: 13 | X15: 66 | AD15: =+R15-X15 -> -53 | AP15: =R15*10*26 -> 3380 | AV15: =X15*10*26 -> 17160 | BB15: =AV15-AP15 -> 13780 | BN15: 30 | BX15: =347*26*8 -> 72176
H16: Total | R16: =SUM(R12:W15) -> 40 | X16: =SUM(X12:AC15) -> 141 | AD16: =+R16-X16 -> -101 | AP16: =SUM(AP12:AU15) -> 10400 | AV16: =SUM(AV12:BA15) -> 36660 | BB16: =SUM(BB12:BG15) -> 26260 | BN16: =SUM(BN12:BR15) -> 65
A17: Sub-Con | R17: 0 | X17: 14 | AD17: =R17-X17 -> -14 | AP17: =R17*26*10 -> 0 | AV17: =X17*26*10 -> 3640 | BB17: =AP17-AV17 -> -3640 | BN17: 0
A20: STB - Standard Tool Box
A22: STB Type | R22: No of Units @ Site | AD22: STB Issued to Worker | AV22: STB Available @ Store | BH22: Additional Requirement If any
A23: Ducting | R23: 5 | AD23: 0 | AV23: 10 | BH23: 0
A24: Piping +A/C Tech. | R24: 0 | AD24: 0 | AV24: 0 | BH24: 0
A25: Plumbing | R25: 0 | AD25: 0 | AV25: 0 | BH25: 0
A26: Electrical + BMS | R26: 5 | AD26: 0 | AV26: 15 | BH26: 0
A27: Remarks
A31: Monthly Unit Workshop
R33: Last Month | AH33: This Month | BD33: Next Month (Forecast)
A34: Plan
A35: Actual - Conducted
A38: *-Approved Manpower plan and Histogram Attached

Sheet 11-Account
G1: R67-M1-15 - Monthly Project Report ACCOUNTS | AR1: Doc. No.: | AW1: REE/OPR/05.10
AR2: Rev.: | AT2: 0 | AW2: 0
AR3: Date: | AT3: 41922 | AW3: =+'Cover '!T11 -> 42460
A5: Petty Cash Expenses Details
A7: Petty Cash Expenses | AS7: Total Petty cash Expenses as of This Month
A8: Upto Last Month | P8: This Month | AE8: Next Month (Expected)
P9: 0 | AE9: 0

Sheet 12-Store
G1: R67-M1-15 - Monthly Project Report STORE | AW1: Doc. No.: | AZ1: REE/OPR/05.11
AW2: Rev.: | AZ2: 1
AW3: Date: | AZ3: =+'Cover '!T11 -> 42460
A5: STOCK VALUE
A7: Discipline | J7: Stock Pervious Month (February - 2016) | AI7: Stock This Month (March - 2016)
J8: Permanent Material | P8: Material which may not be used & need Transfer | V8: Consumable /sundries | AB8: Total | AI8: Permanent Material | AO8: Material which may not be used & need Transfer | AU8: Consumable /sundries | BA8: Total
A9: HVAC | J9: 69746.02 | P9: 0 | V9: 8804.92 | AB9: =SUM(J9:AA9) -> 78550.94 | AI9: 73722.75 | AO9: 0 | AU9: 9138.55 | BA9: =SUM(AI9:AZ9) -> 82861.3 | BI9: 9138.5507 | BJ9: 145667.36 | BL9: =AU9/AU15 -> 0.060445383 | BM9: =BL15*BL9 -> 9138.55
A10: Plumbing | J10: 368156.65 | P10: 0 | V10: 46477.03 | AB10: =SUM(J10:AA10) -> 414633.68 | AI10: 244238.61 | AO10: 0 | AU10: 48238.11 | BA10: =SUM(AI10:AZ10) -> 292476.72 | BI10: 48238.11 | BL10: =AU10/AU15 -> 0.31906276 | BM10: =BL10*BL15 -> 48238.11
A11: Fire Fighting | J11: 106823.61 | P11: 0 | V11: 13485.68 | AB11: =SUM(J11:AA11) -> 120309.29 | AI11: 104909.66 | AO11: 0 | AU11: 13996.67 | BA11: =SUM(AI11:AZ11) -> 118906.33 | BI11: 13996.671 | BJ11: =+AI9/SUM($AI$9+$AI$10+$AI$11+$AI$12) -> 0.097574115 | BK11: =+BJ11*$BJ$9 -> 14213.364 | BL11: =AU11/AU15 -> 0.09257859 | BM11: =BL15*BL11 -> 13996.67
A12: Electrical- MV/ LV | J12: 609142.71 | P12: 0 | V12: 76899.73 | AB12: =SUM(J12:AA12) -> 686042.44 | AI12: 332685.41 | AO12: 0 | AU12: 79813.57 | BA12: =SUM(AI12:AZ12) -> 412498.98 | BI12: 79813.568 | BJ12: =+AI10/SUM($AI$9+$AI$10+$AI$11+$AI$12) -> 0.32325661 | BK12: =+BJ12*$BJ$9 -> 47087.937 | BL12: =AU12/AU15 -> 0.52791326 | BM12: =BL15*BL12 -> 79813.57
A13: Electrical- ELV | BJ13: =+AI11/SUM($AI$9+$AI$10+$AI$11+$AI$12) -> 0.13885086 | BK13: =+BJ13*$BJ$9 -> 20226.038
A14: Tools / Equipment's | J14: 429448.31 | P14: 0 | V14: 0 | AB14: =SUM(J14:AA14) -> 429448.31 | AI14: 323526.01 | AO14: 0 | AU14: 0 | BA14: =SUM(AI14:AZ14) -> 323526.01 | BJ14: =+AI12/SUM($AI$9+$AI$10+$AI$11+$AI$12) -> 0.44031842 | BK14: =+BJ14*$BJ$9 -> 64140.021
A15: G. Total | J15: =SUM(J9:O14) -> 1583317.3 | P15: =SUM(P9:U14) -> 0 | V15: =SUM(V9:AA14) -> 145667.36 | AB15: =SUM(AB9:AH14) -> 1728984.7 | AI15: =SUM(AI9:AN14) -> 1079082.4 | AO15: =SUM(AO9:AT14) -> 0 | AU15: =SUM(AU9:AZ14) -> 151186.9 | BA15: =SUM(BA9:BG14) -> 1230269.3 | BL15: 151186.9 | BM15: =SUM(BM9:BM12) -> 151186.9

Sheet 13-AOC
C1: R67-M1-15 -Monthly Project Report Areas Of Concern | G1: Doc. No.: | H1: REE/OPR/05.12
G2: Rev.: | H2: 1
G3: Date: | H3: =+'Cover '!T11 -> 42460
A5: Areas of Concern
A7: S.# | B7: Concern | D7: Impact | E7: Suggested Action
E8: Action | F8: Action By | I8: Date
A9: 1 | B9: Delivery of Emergency lights for staircase in Palace, chalets & Ancillary buildings | D9: Delay in Installation & Handing Over | E9: Follow up with UCC | F9: Mr. Mohannad Hanna | I9: Weekly
A10: 2 | B10: Delivery of wiring devices | D10: Delaying the MEP Final Fixture Installation | E10: Follow up with UCC | F10: Mr. Mohannad Hanna | I10: Daily
A11: 3 | B11: Civil clearance for Bath Tub Installation in Chalets | D11: Delay the installation in Chalet | E11: Follow up with UCC | F11: Mr. Mohannad Hanna | I11: Daily
A12: 4 | B12: Doors & Windows Installation are delaying | D12: Delay the MEP Air Balancing Testing & Commissioning | E12: Follow up with UCC | F12: Mr. Mohannad Hanna | I12: Daily
A13: 5
A14: 6
A15: 7
A16: 8
A17: 9
A18: 10

Sheet 14-Close-out
B1: R67-M1-15 -Monthly Project Report CLOSE-OUT | F1: Doc. No.: | G1: REE/OPR/05.13
F2: Rev.: | G2: 0
F3: Date: | G3: =+'Cover '!T11 -> 42460
A5: Description | C5: Total | D5: HVAC | E5: FF | F5: PL | H5: Electrical
A6: Material Inspection | B6: Total | C6: =SUM(D6:H6) -> 64 | D6: 37 | H6: =+'5-QA-QC'!K13 -> 27
B7: Code - A | C7: =+D7+H7 -> 25 | D7: 13 | H7: 12
B8: Total to be resubmitted for Code - A | C8: =SUM(D8:H8) -> 39 | D8: 24 | H8: 15
B9: Exp. Date to Complete
A10: Installation Inspection | B10: Total | C10: =SUM(D10:H10) -> 1131 | D10: 608 | H10: 523
B11: Code - A | C11: =SUM(D11:H11) -> 672 | D11: 344 | H11: 328
B12: Total to be resubmitted for Code - A | C12: =SUM(D12:H12) -> 459 | D12: =D10-D11 -> 264 | H12: =H10-H11 -> 195
B13: Exp. Date to Complete
A14: Red Line Drw | B14: Total
B15: Submitted
B16: Approved
B17: Exp. Date to Complete
A18: As-Built | B18: Total | C18: =SUM(D18:H18) -> 457 | D18: 202 | H18: 255
B19: Submitted | C19: =SUM(D19:H19) -> 17 | D19: 9 | H19: 8
B20: Approved | C20: =SUM(D20:H20) -> 0 | D20: 0 | H20: 0
B21: Handed Over
B22: Exp. Date to Complete
A23: T&C Procedure | B23: Total | C23: =SUM(D23:H23) -> 15 | D23: 1 | E23: 4 | F23: 2 | H23: 8
B24: Submitted | C24: =SUM(D24:H24) -> 15 | D24: 1 | E24: 4 | F24: 2 | H24: 8
B25: Approved | C25: =SUM(D25:H25) -> 14 | D25: 1 | E25: 3 | F25: 2 | H25: 8
B26: Procedure Execution | C26: =SUM(D26:H26) -> 10 | D26: 1 | E26: 3 | F26: 2 | H26: 4
B27: T&C Accepted by The Engineer | C27: =SUM(D27:H27) -> 2 | D27: 0 | E27: 0 | F27: 2 | H27: 0
B28: Exp. Date to Complete the T&C
A29: Punch List | B29: Total Received
B30: Work Completed
B31: Punch Item signed by the Engineer / Closed
B32: Exp. Date to Complete
A33: O&M Manual | B33: Total | C33: =SUM(D33:H33) -> 21 | D33: 4 | E33: 4 | F33: 6 | H33: 7
B34: Submitted | C34: =SUM(D34:H34) -> 0 | D34: 0 | E34: 0 | F34: 0 | H34: 0
B35: Approved | C35: =SUM(D35:H35) -> 0 | D35: 0 | E35: 0 | F35: 0 | H35: 0
B36: Handed Over | C36: =SUM(D36:H36) -> 0 | D36: 0 | E36: 0 | F36: 0 | H36: 0
B37: Exp. Date to Complete
A38: Training | B38: Total
B39: Submitted
B40: Approved
B41: Conducted
...

Sheet Sub
F21: Project Report - Monthly
F37: Project Name : xxxxxxx
E78: TABLE OF CONTENTS
E81: Project Overview
E82: § Project
E83: § Program
E84: § Progress
E85: § Progress S - Cuve
E86: § Loo Ahead Program
E87: Engineering
E88: Procurement
E89: QA/QC Status
E90: Resources
E91: § Man-hours
... E106: Admin Report
A133: Project Overview
A136: Project Details
A137: Project:
A139: Client:
A141: Designer:
A143: MEP Designer:
A145: Consultant:
A147: Main Contractor:
A149: MEP Contractor:
A151: In House Sub-Con: | S151: 1
S152: 2
S153: 3
S154: 4
A156: Program Detail
A158: Program Detail | Q158: Rev | U158: Status | AG158: Start Date | AT158: Plan Completion Date | BK158: Projected Completion Date
A163: (A)- Approved, (F) - Followed, (S)-Submitted/under review
A165: Progress Detail
A167: Month | Q167: Plan | AB167: Actual | AL167: Variance
AL168: Total | AW168: EL | BE168: HVAC | BM168: FF | BU168: PL
A169: Pervious
A170: Current
A171: Forecast
A173: Progress- S Curve
A175: 3 Month Look Ahead Plan
A176: (Major Activity only)
...
