Workbook
Name Slicer_1817_BOQ_Summary: #N/A
Name Slicer_1817_BOQ_Summary1: #N/A
Name Slicer_1817_BOQ_Summary11: #N/A
Name Slicer_1817_BOQ_Summary2: #N/A
Name Slicer_1817_Zone: #N/A
Name Slicer_1817_Zone1: #N/A
Name Slicer_1817_Zone11: #N/A
Name Slicer_MonthID: #N/A
Name Slicer_ResourceID1: #N/A
Name Slicer_Week_ID1: #N/A
Name Slicer_WeekID1: #N/A

Sheet Weekly Detailed EVM Hrs
A1: ='Weekly Cost Summary'!A1 -> Project Name | I1: ='Weekly Cost Summary'!N1 -> Data Date: | K1: ='Weekly Cost Summary'!P1 -> 44192
A2: ='Weekly Cost Summary'!A2 -> Location | I2: ='Weekly Cost Summary'!N2 -> Current Week | K2: ='Weekly Cost Summary'!P2 -> 48
I3: ='Weekly Cost Summary'!N3 -> Total Weeks | K3: ='Weekly Cost Summary'!P3 -> 114
A5: 1817-Zone | B5: 1817-BOQ Summary | C5: Activity ID | D5: Activity Name | E5: Budget hrs | F5: Planned Hrs | G5: Earned Hrs | H5: Planned Hrs % Compl. | I5: Planned Weightage % | J5: Actual Weightage % | K5: Actual Hrs % Complete | L5: Hours Productivity
A6: Z1 | B6: Div 01 | C6: PRL-MOB-1020 | D6: Site Office Establishment | E6: 162 | F6: 162 | G6: 124 | H6: =IFERROR(F6/E6,"") -> 1 | I6: =IF(F6/ActivitySum!$C$1300=0%,"",F6/ActivitySum!$C$1300) -> 1.8675707e-06 | J6: =IF(G6/ActivitySum!$C$1300=0%,"",G6/ActivitySum!$C$1300) -> 1.4294985e-06 | K6: =IFERROR(G6/E6,"") -> 0.7654321 | L6: =IFERROR(G6/F6,"") -> 0.7654321
C7: PRL-MOB-1050 | D7: Project Sign Boards and Hoarding | E7: 162 | F7: 162 | G7: 124 | H7: =IFERROR(F7/E7,"") -> 1 | I7: =IF(F7/ActivitySum!$C$1300=0%,"",F7/ActivitySum!$C$1300) -> 1.8675707e-06 | J7: =IF(G7/ActivitySum!$C$1300=0%,"",G7/ActivitySum!$C$1300) -> 1.4294985e-06 | K7: =IFERROR(G7/E7,"") -> 0.7654321 | L7: =IFERROR(G7/F7,"") -> 0.7654321
C8: PRL-MOB-1100 | D8: Yards & Stores Establishment | E8: 190 | F8: 190 | G8: 145 | H8: =IFERROR(F8/E8,"") -> 1 | I8: =IF(F8/ActivitySum!$C$1300=0%,"",F8/ActivitySum!$C$1300) -> 2.1903606e-06 | J8: =IF(G8/ActivitySum!$C$1300=0%,"",G8/ActivitySum!$C$1300) -> 1.671591e-06 | K8: =IFERROR(G8/E8,"") -> 0.76315789 | L8: =IFERROR(G8/F8,"") -> 0.76315789
B9: Div 02 | C9: C-EW-10370 | D9: Excavation Stage 1 - Z1 | E9: 2271 | F9: 2271 | G9: 1249 | H9: =IFERROR(F9/E9,"") -> 1 | I9: =IF(F9/ActivitySum!$C$1300=0%,"",F9/ActivitySum!$C$1300) -> 2.6180574e-05 | J9: =IF(G9/ActivitySum!$C$1300=0%,"",G9/ActivitySum!$C$1300) -> 1.4398739e-05 | K9: =IFERROR(G9/E9,"") -> 0.54997798 | L9: =IFERROR(G9/F9,"") -> 0.54997798
C10: C-EW-10390 | D10: Excavation Stage 2 - Z1 | E10: 2272 | F10: 2272 | G10: 1250 | H10: =IFERROR(F10/E10,"") -> 1 | I10: =IF(F10/ActivitySum!$C$1300=0%,"",F10/ActivitySum!$C$1300) -> 2.6192102e-05 | J10: =IF(G10/ActivitySum!$C$1300=0%,"",G10/ActivitySum!$C$1300) -> 1.4410267e-05 | K10: =IFERROR(G10/E10,"") -> 0.55017606 | L10: =IFERROR(G10/F10,"") -> 0.55017606
C11: C-EW-10450 | D11: Waterproof Membrane on Gunite Wall - Z1-B1 | E11: 200 | F11: 200 | H11: =IFERROR(F11/E11,"") -> 1 | I11: =IF(F11/ActivitySum!$C$1300=0%,"",F11/ActivitySum!$C$1300) -> 2.3056428e-06 | J11: =IF(G11/ActivitySum!$C$1300=0%,"",G11/ActivitySum!$C$1300) | K11: =IFERROR(G11/E11,"") -> 0 | L11: =IFERROR(G11/F11,"") -> 0
C12: C-EW-2430 | D12: Waterproof Membrane on Gunite Wall - Z1-B2 | E12: 200 | F12: 200 | H12: =IFERROR(F12/E12,"") -> 1 | I12: =IF(F12/ActivitySum!$C$1300=0%,"",F12/ActivitySum!$C$1300) -> 2.3056428e-06 | J12: =IF(G12/ActivitySum!$C$1300=0%,"",G12/ActivitySum!$C$1300) | K12: =IFERROR(G12/E12,"") -> 0 | L12: =IFERROR(G12/F12,"") -> 0
C13: C-SHRNG-DCE-C-2330 | D13: Place Guide Wall - Z1 | E13: 249 | F13: 249 | G13: 274 | H13: =IFERROR(F13/E13,"") -> 1 | I13: =IF(F13/ActivitySum!$C$1300=0%,"",F13/ActivitySum!$C$1300) -> 2.8705253e-06 | J13: =IF(G13/ActivitySum!$C$1300=0%,"",G13/ActivitySum!$C$1300) -> 3.1587306e-06 | K13: =IFERROR(G13/E13,"") -> 1.1004016 | L13: =IFERROR(G13/F13,"") -> 1.1004016
C14: C-SHRNG-DCE-C-2350 | D14: Install Capping Beam - Z1 | E14: 2461 | F14: 2461 | G14: 1353 | H14: =IFERROR(F14/E14,"") -> 1 | I14: =IF(F14/ActivitySum!$C$1300=0%,"",F14/ActivitySum!$C$1300) -> 2.8370934e-05 | J14: =IF(G14/ActivitySum!$C$1300=0%,"",G14/ActivitySum!$C$1300) -> 1.5597673e-05 | K14: =IFERROR(G14/E14,"") -> 0.54977651 | L14: =IFERROR(G14/F14,"") -> 0.54977651
C15: PRL-MOB-SCW-2330 | D15: Clearing Existing Utilities | E15: 495 | F15: 495 | G15: 272 | H15: =IFERROR(F15/E15,"") -> 1 | I15: =IF(F15/ActivitySum!$C$1300=0%,"",F15/ActivitySum!$C$1300) -> 5.7064659e-06 | J15: =IF(G15/ActivitySum!$C$1300=0%,"",G15/ActivitySum!$C$1300) -> 3.1356742e-06 | K15: =IFERROR(G15/E15,"") -> 0.54949495 | L15: =IFERROR(G15/F15,"") -> 0.54949495
B16: Div 03 | C16: C-EW-2420 | D16: Gunite Wall - Z1 | E16: 333 | F16: 333 | G16: 283 | H16: =IFERROR(F16/E16,"") -> 1 | I16: =IF(F16/ActivitySum!$C$1300=0%,"",F16/ActivitySum!$C$1300) -> 3.8388952e-06 | J16: =IF(G16/ActivitySum!$C$1300=0%,"",G16/ActivitySum!$C$1300) -> 3.2624845e-06 | K16: =IFERROR(G16/E16,"") -> 0.84984985 | L16: =IFERROR(G16/F16,"") -> 0.84984985
C17: Z1-C-CON-2400 | D17: PCC Blind Concrete - Z1 - Lift Pit | E17: 6 | F17: 6 | G17: 5 | H17: =IFERROR(F17/E17,"") -> 1 | I17: =IF(F17/ActivitySum!$C$1300=0%,"",F17/ActivitySum!$C$1300) -> 6.9169284e-08 | J17: =IF(G17/ActivitySum!$C$1300=0%,"",G17/ActivitySum!$C$1300) -> 5.764107e-08 | K17: =IFERROR(G17/E17,"") -> 0.83333333 | L17: =IFERROR(G17/F17,"") -> 0.83333333
C18: Z1-C-CON-2440 | D18: Waterproof Membrane - Z1 - Lift Pit | E18: 40 | F18: 40 | G18: 34 | H18: =IFERROR(F18/E18,"") -> 1 | I18: =IF(F18/ActivitySum!$C$1300=0%,"",F18/ActivitySum!$C$1300) -> 4.6112856e-07 | J18: =IF(G18/ActivitySum!$C$1300=0%,"",G18/ActivitySum!$C$1300) -> 3.9195927e-07 | K18: =IFERROR(G18/E18,"") -> 0.85 | L18: =IFERROR(G18/F18,"") -> 0.85
C19: Z1-C-CON-2450 | D19: Protection Screed - Z1 - Lift Pit | E19: 24 | F19: 24 | G19: 20 | H19: =IFERROR(F19/E19,"") -> 1 | I19: =IF(F19/ActivitySum!$C$1300=0%,"",F19/ActivitySum!$C$1300) -> 2.7667713e-07 | J19: =IF(G19/ActivitySum!$C$1300=0%,"",G19/ActivitySum!$C$1300) -> 2.3056428e-07 | K19: =IFERROR(G19/E19,"") -> 0.83333333 | L19: =IFERROR(G19/F19,"") -> 0.83333333
C20: Z1-C-CON-2460 | D20: Fix Rebar - Z1 - Lift Pit | E20: 497 | F20: 497 | G20: 422 | H20: =IFERROR(F20/E20,"") -> 1 | I20: =IF(F20/ActivitySum!$C$1300=0%,"",F20/ActivitySum!$C$1300) -> 5.7295223e-06 | J20: =IF(G20/ActivitySum!$C$1300=0%,"",G20/ActivitySum!$C$1300) -> 4.8649063e-06 | K20: =IFERROR(G20/E20,"") -> 0.84909457 | L20: =IFERROR(G20/F20,"") -> 0.84909457
C21: Z1-C-CON-2480 | D21: Pour Concrete - Z1 - Lift Pit | E21: 95 | F21: 95 | G21: 81 | H21: =IFERROR(F21/E21,"") -> 1 | I21: =IF(F21/ActivitySum!$C$1300=0%,"",F21/ActivitySum!$C$1300) -> 1.0951803e-06 | J21: =IF(G21/ActivitySum!$C$1300=0%,"",G21/ActivitySum!$C$1300) -> 9.3378533e-07 | K21: =IFERROR(G21/E21,"") -> 0.85263158 | L21: =IFERROR(G21/F21,"") -> 0.85263158
C22: Z1-C-CON-2500 | D22: PCC Blind Concrete - Z1 - Raft | E22: 196 | F22: 196 | G22: 167 | H22: =IFERROR(F22/E22,"") -> 1 | I22: =IF(F22/ActivitySum!$C$1300=0%,"",F22/ActivitySum!$C$1300) -> 2.2595299e-06 | J22: =IF(G22/ActivitySum!$C$1300=0%,"",G22/ActivitySum!$C$1300) -> 1.9252117e-06 | K22: =IFERROR(G22/E22,"") -> 0.85204082 | L22: =IFERROR(G22/F22,"") -> 0.85204082
C23: Z1-C-CON-2510 | D23: Waterproof Membrane - Z1 - Raft | E23: 1560 | F23: 1560 | G23: 1326 | H23: =IFERROR(F23/E23,"") -> 1 | I23: =IF(F23/ActivitySum!$C$1300=0%,"",F23/ActivitySum!$C$1300) -> 1.7984014e-05 | J23: =IF(G23/ActivitySum!$C$1300=0%,"",G23/ActivitySum!$C$1300) -> 1.5286412e-05 | K23: =IFERROR(G23/E23,"") -> 0.85 | L23: =IFERROR(G23/F23,"") -> 0.85
C24: Z1-C-CON-2520 | D24: Protection Screed - Z1 - Raft | E24: 96 | F24: 96 | G24: 3 | H24: =IFERROR(F24/E24,"") -> 1 | I24: =IF(F24/ActivitySum!$C$1300=0%,"",F24/ActivitySum!$C$1300) -> 1.1067085e-06 | J24: =IF(G24/ActivitySum!$C$1300=0%,"",G24/ActivitySum!$C$1300) -> 3.4584642e-08 | K24: =IFERROR(G24/E24,"") -> 0.03125 | L24: =IFERROR(G24/F24,"") -> 0.03125
C25: Z1-C-CON-2530 | D25: Fix Rebar - Z1 - Raft | E25: 18159 | F25: 18159 | G25: 182 | H25: =IFERROR(F25/E25,"") -> 1 | I25: =IF(F25/ActivitySum!$C$1300=0%,"",F25/ActivitySum!$C$1300) -> 0.00020934084 | J25: =IF(G25/ActivitySum!$C$1300=0%,"",G25/ActivitySum!$C$1300) -> 2.0981349e-06 | K25: =IFERROR(G25/E25,"") -> 0.010022578 | L25: =IFERROR(G25/F25,"") -> 0.010022578
C26: Z1-C-CON-2550 | D26: Fix Formwork - Z1 - Raft | E26: 261 | F26: 261 | G26: 55 | H26: =IFERROR(F26/E26,"") -> 1 | I26: =IF(F26/ActivitySum!$C$1300=0%,"",F26/ActivitySum!$C$1300) -> 3.0088638e-06 | J26: =IF(G26/ActivitySum!$C$1300=0%,"",G26/ActivitySum!$C$1300) -> 6.3405177e-07 | K26: =IFERROR(G26/E26,"") -> 0.21072797 | L26: =IFERROR(G26/F26,"") -> 0.21072797
C27: Z1-C-CON-2560 | D27: Pour Concrete - Z1 - Raft | E27: 4422 | F27: 4422 | G27: 940 | H27: =IFERROR(F27/E27,"") -> 1 | I27: =IF(F27/ActivitySum!$C$1300=0%,"",F27/ActivitySum!$C$1300) -> 5.0977762e-05 | J27: =IF(G27/ActivitySum!$C$1300=0%,"",G27/ActivitySum!$C$1300) -> 1.0836521e-05 | K27: =IFERROR(G27/E27,"") -> 0.2125735 | L27: =IFERROR(G27/F27,"") -> 0.2125735
C28: Z1-C-CON-2570 | D28: Fix Rebar Core Walls - Z1 - B2 | E28: 1609 | F28: 1609 | G28: 342 | H28: =IFERROR(F28/E28,"") -> 1 | I28: =IF(F28/ActivitySum!$C$1300=0%,"",F28/ActivitySum!$C$1300) -> 1.8548896e-05 | J28: =IF(G28/ActivitySum!$C$1300=0%,"",G28/ActivitySum!$C$1300) -> 3.9426492e-06 | K28: =IFERROR(G28/E28,"") -> 0.21255438 | L28: =IFERROR(G28/F28,"") -> 0.21255438
... C74: Z1-C-CON-5950 | D74: Pour Concrete Core Walls Ramp - Z1 - B1 | E74: 152 | F74: 152 | G74: 129 | H74: =IFERROR(F74/E74,"") -> 1 | I74: =IF(F74/ActivitySum!$C$1300=0%,"",F74/ActivitySum!$C$1300) -> 1.7522885e-06 | J74: =IF(G74/ActivitySum!$C$1300=0%,"",G74/ActivitySum!$C$1300) -> 1.4871396e-06 | K74: =IFERROR(G74/E74,"") -> 0.84868421 | L74: =IFERROR(G74/F74,"") -> 0.84868421
B75: Div 04 | C75: Z1-C-FIN-5790 | D75: Masonry Works - Z1 - B2 | E75: 38 | F75: 38 | G75: 2 | H75: =IFERROR(F75/E75,"") -> 1 | I75: =IF(F75/ActivitySum!$C$1300=0%,"",F75/ActivitySum!$C$1300) -> 4.3807213e-07 | J75: =IF(G75/ActivitySum!$C$1300=0%,"",G75/ActivitySum!$C$1300) -> 2.3056428e-08 | K75: =IFERROR(G75/E75,"") -> 0.052631579 | L75: =IFERROR(G75/F75,"") -> 0.052631579
B76: Div 10 | C76: Z1-C-CON-2540 | D76: Fix MEP Provisions - Z1 - Raft | E76: 100 | F76: 100 | G76: 21 | H76: =IFERROR(F76/E76,"") -> 1 | I76: =IF(F76/ActivitySum!$C$1300=0%,"",F76/ActivitySum!$C$1300) -> 1.1528214e-06 | J76: =IF(G76/ActivitySum!$C$1300=0%,"",G76/ActivitySum!$C$1300) -> 2.4209249e-07 | K76: =IFERROR(G76/E76,"") -> 0.21 | L76: =IFERROR(G76/F76,"") -> 0.21
B77: Div 15 | C77: Z1-C-MEP-5810 | D77: Fix G.I Box and conduits - Z1 - B2 | E77: 50 | F77: 29 | G77: 26 | H77: =IFERROR(F77/E77,"") -> 0.58 | I77: =IF(F77/ActivitySum!$C$1300=0%,"",F77/ActivitySum!$C$1300) -> 3.343182e-07 | J77: =IF(G77/ActivitySum!$C$1300=0%,"",G77/ActivitySum!$C$1300) -> 2.9973356e-07 | K77: =IFERROR(G77/E77,"") -> 0.52 | L77: =IFERROR(G77/F77,"") -> 0.89655172
A78: Z2 | B78: Div 02 | C78: C-EW-10400 | D78: Excavation Stage 2 - Z2&3 | E78: 3408 | F78: 3408 | G78: 2207 | H78: =IFERROR(F78/E78,"") -> 1 | I78: =IF(F78/ActivitySum!$C$1300=0%,"",F78/ActivitySum!$C$1300) -> 3.9288153e-05 | J78: =IF(G78/ActivitySum!$C$1300=0%,"",G78/ActivitySum!$C$1300) -> 2.5442768e-05 | K78: =IFERROR(G78/E78,"") -> 0.6475939 | L78: =IFERROR(G78/F78,"") -> 0.6475939
C79: C-EW-10440 | D79: Excavation Stage 1 - Z2&3 | E79: 3409 | F79: 3409 | G79: 2082 | H79: =IFERROR(F79/E79,"") -> 1 | I79: =IF(F79/ActivitySum!$C$1300=0%,"",F79/ActivitySum!$C$1300) -> 3.9299681e-05 | J79: =IF(G79/ActivitySum!$C$1300=0%,"",G79/ActivitySum!$C$1300) -> 2.4001741e-05 | K79: =IFERROR(G79/E79,"") -> 0.61073629 | L79: =IFERROR(G79/F79,"") -> 0.61073629
C80: C-EW-10460 | D80: Waterproof Membrane on Gunite Wall - Z2-B1 | E80: 200 | F80: 200 | H80: =IFERROR(F80/E80,"") -> 1 | I80: =IF(F80/ActivitySum!$C$1300=0%,"",F80/ActivitySum!$C$1300) -> 2.3056428e-06 | J80: =IF(G80/ActivitySum!$C$1300=0%,"",G80/ActivitySum!$C$1300) | K80: =IFERROR(G80/E80,"") -> 0 | L80: =IFERROR(G80/F80,"") -> 0
C81: C-EW-10480 | D81: Gunite Wall - Z3 | E81: 333 | F81: 333 | H81: =IFERROR(F81/E81,"") -> 1 | I81: =IF(F81/ActivitySum!$C$1300=0%,"",F81/ActivitySum!$C$1300) -> 3.8388952e-06 | J81: =IF(G81/ActivitySum!$C$1300=0%,"",G81/ActivitySum!$C$1300) | K81: =IFERROR(G81/E81,"") -> 0 | L81: =IFERROR(G81/F81,"") -> 0
C82: C-SHRNG-DCE-C-2360 | D82: Place Guide Wall - Z2&3 | E82: 249 | F82: 249 | G82: 274 | H82: =IFERROR(F82/E82,"") -> 1 | I82: =IF(F82/ActivitySum!$C$1300=0%,"",F82/ActivitySum!$C$1300) -> 2.8705253e-06 | J82: =IF(G82/ActivitySum!$C$1300=0%,"",G82/ActivitySum!$C$1300) -> 3.1587306e-06 | K82: =IFERROR(G82/E82,"") -> 1.1004016 | L82: =IFERROR(G82/F82,"") -> 1.1004016
C83: C-SHRNG-DCE-C-2380 | D83: Install Capping Beam - Z2&3 | E83: 3692 | F83: 3692 | G83: 4062 | H83: =IFERROR(F83/E83,"") -> 1 | I83: =IF(F83/ActivitySum!$C$1300=0%,"",F83/ActivitySum!$C$1300) -> 4.2562166e-05 | J83: =IF(G83/ActivitySum!$C$1300=0%,"",G83/ActivitySum!$C$1300) -> 4.6827605e-05 | K83: =IFERROR(G83/E83,"") -> 1.1002167 | L83: =IFERROR(G83/F83,"") -> 1.1002167
C84: Z2-C-EW-10420 | D84: Waterproof Membrane on Gunite Wall - Z2-B2 | E84: 200 | F84: 200 | H84: =IFERROR(F84/E84,"") -> 1 | I84: =IF(F84/ActivitySum!$C$1300=0%,"",F84/ActivitySum!$C$1300) -> 2.3056428e-06 | J84: =IF(G84/ActivitySum!$C$1300=0%,"",G84/ActivitySum!$C$1300) | K84: =IFERROR(G84/E84,"") -> 0 | L84: =IFERROR(G84/F84,"") -> 0
B85: Div 03 | C85: C-EW-10410 | D85: Gunite Wall - Z2 | E85: 333 | F85: 333 | G85: 3 | H85: =IFERROR(F85/E85,"") -> 1 | I85: =IF(F85/ActivitySum!$C$1300=0%,"",F85/ActivitySum!$C$1300) -> 3.8388952e-06 | J85: =IF(G85/ActivitySum!$C$1300=0%,"",G85/ActivitySum!$C$1300) -> 3.4584642e-08 | K85: =IFERROR(G85/E85,"") -> 0.009009009 | L85: =IFERROR(G85/F85,"") -> 0.009009009
C86: Z2-C-CON-5840 | D86: PCC Blind Concrete - Z2 - Lift Pit | E86: 4 | F86: 4 | G86: 0 | H86: =IFERROR(F86/E86,"") -> 1 | I86: =IF(F86/ActivitySum!$C$1300=0%,"",F86/ActivitySum!$C$1300) -> 4.6112856e-08 | J86: =IF(G86/ActivitySum!$C$1300=0%,"",G86/ActivitySum!$C$1300) | K86: =IFERROR(G86/E86,"") -> 0 | L86: =IFERROR(G86/F86,"") -> 0
...

Sheet Weekly Hrs Summary
A1: ='Weekly Detailed EVM Hrs'!A1 -> Project Name | F1: Weekly Progress Hours Summary | N1: Data Date: | P1: =INDEX(WeekDates[WeekDates],MATCH('Weekly Hrs Summary'!$P$2,WeekDates[WeekID],)) -> 44192
A2: ='Weekly Detailed EVM Hrs'!A2 -> Location | N2: Current Week | P2: =MAX(U:U) -> 48
A3: BOQ Item Wise Summary | N3: Total Weeks | P3: 114
A4: 1817-BOQ Summary | B4: Budget Hrs | C4: Planned Hrs | D4: Earned Hrs | E4: Planned Hrs % | F4: Actual Hrs % | I4: =A4 -> 1817-BOQ Summary | J4: =B4 -> Budget Hrs | K4: =C4 -> Planned Hrs | L4: =D4 -> Earned Hrs | M4: =E4 -> Planned Hrs %
A5: Div 01 | B5: 514 | C5: 514 | D5: 393 | E5: =C5/B5 -> 1 | F5: =D5/B5 -> 0.76459144 | I5: =A5 -> Div 01 | J5: =B5 -> 514 | K5: =C5 -> 514 | L5: =D5 -> 393 | M5: =E5 -> 1
A6: Div 02 | B6: 20039 | C6: 20039 | D6: 13023 | E6: =C6/B6 -> 1 | F6: =D6/B6 -> 0.64988273 | I6: =A6 -> Div 02 | J6: =B6 -> 20039 | K6: =C6 -> 20039 | L6: =D6 -> 13023 | M6: =E6 -> 1
A7: Div 03 | B7: 377918 | C7: 187385 | D7: 118812 | E7: =C7/B7 -> 0.49583508 | F7: =D7/B7 -> 0.31438566 | I7: =A7 -> Div 03 | J7: =B7 -> 377918 | K7: =C7 -> 187385 | L7: =D7 -> 118812 | M7: =E7 -> 0.49583508 | U7: Row Labels | V7: Sum of WeekID
A8: Div 04 | B8: 22530 | C8: 38 | D8: 1762 | E8: =C8/B8 -> 0.00168664 | F8: =D8/B8 -> 0.078206835 | I8: =A8 -> Div 04 | J8: =B8 -> 22530 | K8: =C8 -> 38 | L8: =D8 -> 1762 | M8: =E8 -> 0.00168664 | U8: 1 | V8: 1
A9: Div 05 | B9: 6395 | D9: 13 | E9: =C9/B9 -> 0 | F9: =D9/B9 -> 0.0020328382 | I9: =A9 -> Div 05 | J9: =B9 -> 6395 | K9: =C9 -> 0 | L9: =D9 -> 13 | M9: =E9 -> 0 | U9: 2 | V9: 2
A10: Div 06 | B10: 1800 | E10: =C10/B10 -> 0 | F10: =D10/B10 -> 0 | I10: =A10 -> Div 06 | J10: =B10 -> 1800 | K10: =C10 -> 0 | L10: =D10 -> 0 | M10: =E10 -> 0 | U10: 3 | V10: 3
A11: Div 07 | B11: 15326 | E11: =C11/B11 -> 0 | F11: =D11/B11 -> 0 | I11: =A11 -> Div 07 | J11: =B11 -> 15326 | K11: =C11 -> 0 | L11: =D11 -> 0 | M11: =E11 -> 0 | U11: 4 | V11: 4
A12: Div 08 | B12: 12173 | D12: 333 | E12: =C12/B12 -> 0 | F12: =D12/B12 -> 0.027355623 | I12: =A12 -> Div 08 | J12: =B12 -> 12173 | K12: =C12 -> 0 | L12: =D12 -> 333 | M12: =E12 -> 0 | U12: 5 | V12: 5
A13: Div 09 | B13: 239501 | D13: 21091 | E13: =C13/B13 -> 0 | F13: =D13/B13 -> 0.088062263 | I13: =A13 -> Div 09 | J13: =B13 -> 239501 | K13: =C13 -> 0 | L13: =D13 -> 21091 | M13: =E13 -> 0 | U13: 6 | V13: 6
A14: Div 10 | B14: 16004 | C14: 300 | D14: 844 | E14: =C14/B14 -> 0.018745314 | F14: =D14/B14 -> 0.052736816 | I14: =A14 -> Div 10 | J14: =B14 -> 16004 | K14: =C14 -> 300 | L14: =D14 -> 844 | M14: =E14 -> 0.018745314 | U14: 7 | V14: 7
A15: Div 11 | B15: 15404 | D15: 1122 | E15: =C15/B15 -> 0 | F15: =D15/B15 -> 0.072838224 | I15: =A15 -> Div 11 | J15: =B15 -> 15404 | K15: =C15 -> 0 | L15: =D15 -> 1122 | M15: =E15 -> 0 | U15: 8 | V15: 8
A16: Div 12 | B16: 27542 | D16: 2269 | E16: =C16/B16 -> 0 | F16: =D16/B16 -> 0.082383269 | I16: =A16 -> Div 12 | J16: =B16 -> 27542 | K16: =C16 -> 0 | L16: =D16 -> 2269 | M16: =E16 -> 0 | U16: 9 | V16: 9
A17: Div 13 | B17: 4682 | E17: =C17/B17 -> 0 | F17: =D17/B17 -> 0 | I17: =A17 -> Div 13 | J17: =B17 -> 4682 | K17: =C17 -> 0 | L17: =D17 -> 0 | M17: =E17 -> 0 | U17: 10 | V17: 10
A18: Div 14 | B18: 2173 | E18: =C18/B18 -> 0 | F18: =D18/B18 -> 0 | I18: =A18 -> Div 14 | J18: =B18 -> 2173 | K18: =C18 -> 0 | L18: =D18 -> 0 | M18: =E18 -> 0 | U18: 11 | V18: 11
A19: Div 15 | B19: 29297 | C19: 29 | D19: 2150 | E19: =C19/B19 -> 0.00098986244 | F19: =D19/B19 -> 0.073386354 | I19: =A19 -> Div 15 | J19: =B19 -> 29297 | K19: =C19 -> 29 | L19: =D19 -> 2150 | M19: =E19 -> 0.00098986244 | U19: 12 | V19: 12
A20: Grand Total | B20: 791298 | C20: 208305 | D20: 161812 | E20: =C20/B20 -> 0.26324469 | F20: =D20/B20 -> 0.20448933 | I20: =A20 -> Grand Total | J20: =B20 -> 791298 | K20: =C20 -> 208305 | L20: =D20 -> 161812 | M20: =E20 -> 0.26324469 | U20: 13 | V20: 13
U21: 14 | V21: 14
A22: Trade Item Wise Summary | U22: 15 | V22: 15
A23: 1817-Trade | B23: Budget Hrs | C23: Planned Hrs | D23: Earned Hrs | E23: Planned Hrs % | F23: Actual Hrs % | I23: =A23 -> 1817-Trade | J23: =B23 -> Budget Hrs | K23: =C23 -> Planned Hrs | L23: =D23 -> Earned Hrs | M23: =E23 -> Planned Hrs % | N23: =F23 -> Actual Hrs % | U23: 16 | V23: 16
A24: Anti-Fungal & Carbonation | B24: 12793 | D24: 3224 | E24: =C24/B24 -> 0 | F24: =D24/B24 -> 0.25201282 | I24: =A24 -> Anti-Fungal & Carbonation | J24: =B24 -> 12793 | K24: =C24 -> 0 | L24: =D24 -> 3224 | M24: =E24 -> 0 | N24: =F24 -> 0.25201282 | U24: 17 | V24: 17
A25: Ceramic | B25: 12431 | E25: =C25/B25 -> 0 | F25: =D25/B25 -> 0 | I25: =A25 -> Ceramic | J25: =B25 -> 12431 | K25: =C25 -> 0 | L25: =D25 -> 0 | M25: =E25 -> 0 | N25: =F25 -> 0 | U25: 18 | V25: 18
A26: Concrete | B26: 377918 | C26: 187385 | D26: 118812 | E26: =C26/B26 -> 0.49583508 | F26: =D26/B26 -> 0.31438566 | I26: =A26 -> Concrete | J26: =B26 -> 377918 | K26: =C26 -> 187385 | L26: =D26 -> 118812 | M26: =E26 -> 0.49583508 | N26: =F26 -> 0.31438566 | U26: 19 | V26: 19
A27: Conveying System | B27: 4682 | E27: =C27/B27 -> 0 | F27: =D27/B27 -> 0 | I27: =A27 -> Conveying System | J27: =B27 -> 4682 | K27: =C27 -> 0 | L27: =D27 -> 0 | M27: =E27 -> 0 | N27: =F27 -> 0 | U27: 20 | V27: 20
A28: Doors | B28: 5692 | D28: 333 | E28: =C28/B28 -> 0 | F28: =D28/B28 -> 0.058503162 | I28: =A28 -> Doors | J28: =B28 -> 5692 | K28: =C28 -> 0 | L28: =D28 -> 333 | M28: =E28 -> 0 | N28: =F28 -> 0.058503162 | U28: 21 | V28: 21
A29: Electrical | B29: 28801 | C29: 29 | D29: 2150 | E29: =C29/B29 -> 0.0010069095 | F29: =D29/B29 -> 0.074650186 | I29: =A29 -> Electrical | J29: =B29 -> 28801 | K29: =C29 -> 29 | L29: =D29 -> 2150 | M29: =E29 -> 0.0010069095 | N29: =F29 -> 0.074650186 | U29: 22 | V29: 22
A30: Epoxy & Traffic Coating | B30: 4452 | D30: 24 | E30: =C30/B30 -> 0 | F30: =D30/B30 -> 0.0053908356 | I30: =A30 -> Epoxy & Traffic Coating | J30: =B30 -> 4452 | K30: =C30 -> 0 | L30: =D30 -> 24 | M30: =E30 -> 0 | N30: =F30 -> 0.0053908356 | U30: 23 | V30: 23
A31: False Ceiling | B31: 20728 | D31: 7 | E31: =C31/B31 -> 0 | F31: =D31/B31 -> 0.00033770745 | I31: =A31 -> False Ceiling | J31: =B31 -> 20728 | K31: =C31 -> 0 | L31: =D31 -> 7 | M31: =E31 -> 0 | N31: =F31 -> 0.00033770745 | U31: 24 | V31: 24
A32: Fire Fighting | B32: 15404 | D32: 1122 | E32: =C32/B32 -> 0 | F32: =D32/B32 -> 0.072838224 | I32: =A32 -> Fire Fighting | J32: =B32 -> 15404 | K32: =C32 -> 0 | L32: =D32 -> 1122 | M32: =E32 -> 0 | N32: =F32 -> 0.072838224 | U32: 25 | V32: 25
A33: Glazing | B33: 5473 | E33: =C33/B33 -> 0 | F33: =D33/B33 -> 0 | I33: =A33 -> Glazing | J33: =B33 -> 5473 | K33: =C33 -> 0 | L33: =D33 -> 0 | M33: =E33 -> 0 | N33: =F33 -> 0 | U33: 26 | V33: 26
A34: HVAC | B34: 27438 | D34: 2269 | E34: =C34/B34 -> 0 | F34: =D34/B34 -> 0.082695532 | I34: =A34 -> HVAC | J34: =B34 -> 27438 | K34: =C34 -> 0 | L34: =D34 -> 2269 | M34: =E34 -> 0 | N34: =F34 -> 0.082695532 | U34: 27 | V34: 27
A35: LPG System | B35: 2173 | E35: =C35/B35 -> 0 | F35: =D35/B35 -> 0 | I35: =A35 -> LPG System | J35: =B35 -> 2173 | K35: =C35 -> 0 | L35: =D35 -> 0 | M35: =E35 -> 0 | N35: =F35 -> 0 | U35: 28 | V35: 28
A36: Masonry | B36: 22530 | C36: 38 | D36: 1762 | E36: =C36/B36 -> 0.00168664 | F36: =D36/B36 -> 0.078206835 | I36: =A36 -> Masonry | J36: =B36 -> 22530 | K36: =C36 -> 38 | L36: =D36 -> 1762 | M36: =E36 -> 0.00168664 | N36: =F36 -> 0.078206835 | U36: 29 | V36: 29
A37: Natural Stone | B37: 13058 | E37: =C37/B37 -> 0 | F37: =D37/B37 -> 0 | I37: =A37 -> Natural Stone | J37: =B37 -> 13058 | K37: =C37 -> 0 | L37: =D37 -> 0 | M37: =E37 -> 0 | N37: =F37 -> 0 | U37: 30 | V37: 30
A38: Others Finishes | B38: 36854 | D38: 13 | E38: =C38/B38 -> 0 | F38: =D38/B38 -> 0.00035274326 | I38: =A38 -> Others Finishes | J38: =B38 -> 36854 | K38: =C38 -> 0 | L38: =D38 -> 13 | M38: =E38 -> 0 | N38: =F38 -> 0.00035274326 | U38: 31 | V38: 31
A39: Paint | B39: 18963 | D39: 2067 | E39: =C39/B39 -> 0 | F39: =D39/B39 -> 0.10900174 | I39: =A39 -> Paint | J39: =B39 -> 18963 | K39: =C39 -> 0 | L39: =D39 -> 2067 | M39: =E39 -> 0 | N39: =F39 -> 0.10900174 | U39: 32 | V39: 32
A40: Plaster | B40: 112175 | D40: 15634 | E40: =C40/B40 -> 0 | F40: =D40/B40 -> 0.13937152 | I40: =A40 -> Plaster | J40: =B40 -> 112175 | K40: =C40 -> 0 | L40: =D40 -> 15634 | M40: =E40 -> 0 | N40: =F40 -> 0.13937152 | U40: 33 | V40: 33
...

Sheet Weekly Detailed EVM Cost
A1: ='Weekly Cost Summary'!A1 -> Project Name | I1: ='Weekly Cost Summary'!N1 -> Data Date: | K1: ='Weekly Cost Summary'!P1 -> 44192
A2: ='Weekly Cost Summary'!A2 -> Location | I2: ='Weekly Cost Summary'!N2 -> Current Week | K2: ='Weekly Cost Summary'!P2 -> 48
I3: ='Weekly Cost Summary'!N3 -> Total Weeks | K3: ='Weekly Cost Summary'!P3 -> 114
A5: 1817-Zone | B5: 1817-BOQ Summary | C5: Activity ID | D5: Activity Name | E5: Budget Cost | F5: Planned Cost | G5: Earned Cost | H5: Planned Cost % Compl. | I5: Planned Weightage % | J5: Actual Weightage % | K5: Actual Cost % Complete | L5: SPI
A6: Z1 | B6: Div 01 | C6: PRL-MOB-1020 | D6: Site Office Establishment | E6: 767001 | F6: 767001 | G6: 586756 | H6: =IFERROR(F6/E6,"") -> 1 | I6: =IF(F6/ActivitySum!$C$1300=0%,"",F6/ActivitySum!$C$1300) -> 0.0088421516 | J6: =IF(G6/ActivitySum!$C$1300=0%,"",G6/ActivitySum!$C$1300) -> 0.0067642487 | K6: =IFERROR(G6/E6,"") -> 0.76500031 | L6: =IFERROR(G6/F6,"") -> 0.76500031
C7: PRL-MOB-1050 | D7: Project Sign Boards and Hoarding | E7: 60000 | F7: 60000 | G7: 45900 | H7: =IFERROR(F7/E7,"") -> 1 | I7: =IF(F7/ActivitySum!$C$1300=0%,"",F7/ActivitySum!$C$1300) -> 0.00069169284 | J7: =IF(G7/ActivitySum!$C$1300=0%,"",G7/ActivitySum!$C$1300) -> 0.00052914502 | K7: =IFERROR(G7/E7,"") -> 0.765 | L7: =IFERROR(G7/F7,"") -> 0.765
C8: PRL-MOB-1100 | D8: Yards & Stores Establishment | E8: 80000 | F8: 80000 | G8: 61200 | H8: =IFERROR(F8/E8,"") -> 1 | I8: =IF(F8/ActivitySum!$C$1300=0%,"",F8/ActivitySum!$C$1300) -> 0.00092225711 | J8: =IF(G8/ActivitySum!$C$1300=0%,"",G8/ActivitySum!$C$1300) -> 0.00070552669 | K8: =IFERROR(G8/E8,"") -> 0.765 | L8: =IFERROR(G8/F8,"") -> 0.765
B9: Div 02 | C9: C-EW-10370 | D9: Excavation Stage 1 - Z1 | E9: 293640 | F9: 293640 | G9: 161502 | H9: =IFERROR(F9/E9,"") -> 1 | I9: =IF(F9/ActivitySum!$C$1300=0%,"",F9/ActivitySum!$C$1300) -> 0.0033851447 | J9: =IF(G9/ActivitySum!$C$1300=0%,"",G9/ActivitySum!$C$1300) -> 0.0018618296 | K9: =IFERROR(G9/E9,"") -> 0.55 | L9: =IFERROR(G9/F9,"") -> 0.55
C10: C-EW-10380 | D10: Strut Pipe Bracing - Z1 | E10: 162250 | F10: 162250 | G10: 178476 | H10: =IFERROR(F10/E10,"") -> 1 | I10: =IF(F10/ActivitySum!$C$1300=0%,"",F10/ActivitySum!$C$1300) -> 0.0018704527 | J10: =IF(G10/ActivitySum!$C$1300=0%,"",G10/ActivitySum!$C$1300) -> 0.0020575095 | K10: =IFERROR(G10/E10,"") -> 1.1000062 | L10: =IFERROR(G10/F10,"") -> 1.1000062
C11: C-EW-10390 | D11: Excavation Stage 2 - Z1 | E11: 293641 | F11: 293641 | G11: 161503 | H11: =IFERROR(F11/E11,"") -> 1 | I11: =IF(F11/ActivitySum!$C$1300=0%,"",F11/ActivitySum!$C$1300) -> 0.0033851563 | J11: =IF(G11/ActivitySum!$C$1300=0%,"",G11/ActivitySum!$C$1300) -> 0.0018618411 | K11: =IFERROR(G11/E11,"") -> 0.55000153 | L11: =IFERROR(G11/F11,"") -> 0.55000153
C12: C-SHRNG-DCE-C-2330 | D12: Place Guide Wall - Z1 | E12: 162250 | F12: 162250 | G12: 178476 | H12: =IFERROR(F12/E12,"") -> 1 | I12: =IF(F12/ActivitySum!$C$1300=0%,"",F12/ActivitySum!$C$1300) -> 0.0018704527 | J12: =IF(G12/ActivitySum!$C$1300=0%,"",G12/ActivitySum!$C$1300) -> 0.0020575095 | K12: =IFERROR(G12/E12,"") -> 1.1000062 | L12: =IFERROR(G12/F12,"") -> 1.1000062
C13: C-SHRNG-DCE-C-2340 | D13: Install Shoring System - Z1 | E13: 2016502 | F13: 2016501 | G13: 2218152 | H13: =IFERROR(F13/E13,"") -> 0.9999995 | I13: =IF(F13/ActivitySum!$C$1300=0%,"",F13/ActivitySum!$C$1300) -> 0.023246655 | J13: =IF(G13/ActivitySum!$C$1300=0%,"",G13/ActivitySum!$C$1300) -> 0.025571331 | K13: =IFERROR(G13/E13,"") -> 1.0999999 | L13: =IFERROR(G13/F13,"") -> 1.1000004
C14: C-SHRNG-DCE-C-2350 | D14: Install Capping Beam - Z1 | E14: 180856 | F14: 180856 | G14: 99471 | H14: =IFERROR(F14/E14,"") -> 1 | I14: =IF(F14/ActivitySum!$C$1300=0%,"",F14/ActivitySum!$C$1300) -> 0.0020849467 | J14: =IF(G14/ActivitySum!$C$1300=0%,"",G14/ActivitySum!$C$1300) -> 0.001146723 | K14: =IFERROR(G14/E14,"") -> 0.55000111 | L14: =IFERROR(G14/F14,"") -> 0.55000111
C15: PRL-MOB-SCW-1600 | D15: Soil Investigation & Report Submit | E15: 55000 | F15: 55000 | G15: 42075 | H15: =IFERROR(F15/E15,"") -> 1 | I15: =IF(F15/ActivitySum!$C$1300=0%,"",F15/ActivitySum!$C$1300) -> 0.00063405177 | J15: =IF(G15/ActivitySum!$C$1300=0%,"",G15/ActivitySum!$C$1300) -> 0.0004850496 | K15: =IFERROR(G15/E15,"") -> 0.765 | L15: =IFERROR(G15/F15,"") -> 0.765
C16: PRL-MOB-SCW-2310 | D16: Dewatering System Installation | E16: 95000 | F16: 95000 | G16: 104500 | H16: =IFERROR(F16/E16,"") -> 1 | I16: =IF(F16/ActivitySum!$C$1300=0%,"",F16/ActivitySum!$C$1300) -> 0.0010951803 | J16: =IF(G16/ActivitySum!$C$1300=0%,"",G16/ActivitySum!$C$1300) -> 0.0012046984 | K16: =IFERROR(G16/E16,"") -> 1.1 | L16: =IFERROR(G16/F16,"") -> 1.1
C17: PRL-MOB-SCW-2320 | D17: Demolition of Existing Structure | E17: 140001 | F17: 140001 | G17: 77001 | H17: =IFERROR(F17/E17,"") -> 1 | I17: =IF(F17/ActivitySum!$C$1300=0%,"",F17/ActivitySum!$C$1300) -> 0.0016139615 | J17: =IF(G17/ActivitySum!$C$1300=0%,"",G17/ActivitySum!$C$1300) -> 0.000887684 | K17: =IFERROR(G17/E17,"") -> 0.55000321 | L17: =IFERROR(G17/F17,"") -> 0.55000321
C18: PRL-MOB-SCW-2330 | D18: Clearing Existing Utilities | E18: 39000 | F18: 39000 | G18: 21450 | H18: =IFERROR(F18/E18,"") -> 1 | I18: =IF(F18/ActivitySum!$C$1300=0%,"",F18/ActivitySum!$C$1300) -> 0.00044960034 | J18: =IF(G18/ActivitySum!$C$1300=0%,"",G18/ActivitySum!$C$1300) -> 0.00024728019 | K18: =IFERROR(G18/E18,"") -> 0.55 | L18: =IFERROR(G18/F18,"") -> 0.55
B19: Div 03 | C19: C-EW-2420 | D19: Gunite Wall - Z1 | E19: 152558 | F19: 152558 | G19: 129675 | H19: =IFERROR(F19/E19,"") -> 1 | I19: =IF(F19/ActivitySum!$C$1300=0%,"",F19/ActivitySum!$C$1300) -> 0.0017587213 | J19: =IF(G19/ActivitySum!$C$1300=0%,"",G19/ActivitySum!$C$1300) -> 0.0014949211 | K19: =IFERROR(G19/E19,"") -> 0.85000459 | L19: =IFERROR(G19/F19,"") -> 0.85000459
C20: Z1-C-CON-2400 | D20: PCC Blind Concrete - Z1 - Lift Pit | E20: 17220 | F20: 17220 | G20: 14637 | H20: =IFERROR(F20/E20,"") -> 1 | I20: =IF(F20/ActivitySum!$C$1300=0%,"",F20/ActivitySum!$C$1300) -> 0.00019851584 | J20: =IF(G20/ActivitySum!$C$1300=0%,"",G20/ActivitySum!$C$1300) -> 0.00016873847 | K20: =IFERROR(G20/E20,"") -> 0.85 | L20: =IFERROR(G20/F20,"") -> 0.85
C21: Z1-C-CON-2440 | D21: Waterproof Membrane - Z1 - Lift Pit | E21: 102280 | F21: 102280 | G21: 86938 | H21: =IFERROR(F21/E21,"") -> 1 | I21: =IF(F21/ActivitySum!$C$1300=0%,"",F21/ActivitySum!$C$1300) -> 0.0011791057 | J21: =IF(G21/ActivitySum!$C$1300=0%,"",G21/ActivitySum!$C$1300) -> 0.0010022399 | K21: =IFERROR(G21/E21,"") -> 0.85 | L21: =IFERROR(G21/F21,"") -> 0.85
C22: Z1-C-CON-2450 | D22: Protection Screed - Z1 - Lift Pit | E22: 10980 | F22: 10980 | G22: 9333 | H22: =IFERROR(F22/E22,"") -> 1 | I22: =IF(F22/ActivitySum!$C$1300=0%,"",F22/ActivitySum!$C$1300) -> 0.00012657979 | J22: =IF(G22/ActivitySum!$C$1300=0%,"",G22/ActivitySum!$C$1300) -> 0.00010759282 | K22: =IFERROR(G22/E22,"") -> 0.85 | L22: =IFERROR(G22/F22,"") -> 0.85
C23: Z1-C-CON-2460 | D23: Fix Rebar - Z1 - Lift Pit | E23: 20247 | F23: 20247 | G23: 17210 | H23: =IFERROR(F23/E23,"") -> 1 | I23: =IF(F23/ActivitySum!$C$1300=0%,"",F23/ActivitySum!$C$1300) -> 0.00023341175 | J23: =IF(G23/ActivitySum!$C$1300=0%,"",G23/ActivitySum!$C$1300) -> 0.00019840056 | K23: =IFERROR(G23/E23,"") -> 0.85000247 | L23: =IFERROR(G23/F23,"") -> 0.85000247
C24: Z1-C-CON-2480 | D24: Pour Concrete - Z1 - Lift Pit | E24: 20247 | F24: 20247 | G24: 17210 | H24: =IFERROR(F24/E24,"") -> 1 | I24: =IF(F24/ActivitySum!$C$1300=0%,"",F24/ActivitySum!$C$1300) -> 0.00023341175 | J24: =IF(G24/ActivitySum!$C$1300=0%,"",G24/ActivitySum!$C$1300) -> 0.00019840056 | K24: =IFERROR(G24/E24,"") -> 0.85000247 | L24: =IFERROR(G24/F24,"") -> 0.85000247
C25: Z1-C-CON-2500 | D25: PCC Blind Concrete - Z1 - Raft | E25: 51660 | F25: 51660 | G25: 43911 | H25: =IFERROR(F25/E25,"") -> 1 | I25: =IF(F25/ActivitySum!$C$1300=0%,"",F25/ActivitySum!$C$1300) -> 0.00059554753 | J25: =IF(G25/ActivitySum!$C$1300=0%,"",G25/ActivitySum!$C$1300) -> 0.0005062154 | K25: =IFERROR(G25/E25,"") -> 0.85 | L25: =IFERROR(G25/F25,"") -> 0.85
C26: Z1-C-CON-2510 | D26: Waterproof Membrane - Z1 - Raft | E26: 306840 | F26: 306840 | G26: 260814 | H26: =IFERROR(F26/E26,"") -> 1 | I26: =IF(F26/ActivitySum!$C$1300=0%,"",F26/ActivitySum!$C$1300) -> 0.0035373172 | J26: =IF(G26/ActivitySum!$C$1300=0%,"",G26/ActivitySum!$C$1300) -> 0.0030067196 | K26: =IFERROR(G26/E26,"") -> 0.85 | L26: =IFERROR(G26/F26,"") -> 0.85
C27: Z1-C-CON-2520 | D27: Protection Screed - Z1 - Raft | E27: 32940 | F27: 32940 | G27: 988 | H27: =IFERROR(F27/E27,"") -> 1 | I27: =IF(F27/ActivitySum!$C$1300=0%,"",F27/ActivitySum!$C$1300) -> 0.00037973937 | J27: =IF(G27/ActivitySum!$C$1300=0%,"",G27/ActivitySum!$C$1300) -> 1.1389875e-05 | K27: =IFERROR(G27/E27,"") -> 0.029993928 | L27: =IFERROR(G27/F27,"") -> 0.029993928
C28: Z1-C-CON-2530 | D28: Fix Rebar - Z1 - Raft | E28: 687066 | F28: 687066 | G28: 6871 | H28: =IFERROR(F28/E28,"") -> 1 | I28: =IF(F28/ActivitySum!$C$1300=0%,"",F28/ActivitySum!$C$1300) -> 0.0079206438 | J28: =IF(G28/ActivitySum!$C$1300=0%,"",G28/ActivitySum!$C$1300) -> 7.9210358e-05 | K28: =IFERROR(G28/E28,"") -> 0.010000495 | L28: =IFERROR(G28/F28,"") -> 0.010000495
C29: Z1-C-CON-2550 | D29: Fix Formwork - Z1 - Raft | E29: 41321 | F29: 41321 | G29: 8781 | H29: =IFERROR(F29/E29,"") -> 1 | I29: =IF(F29/ActivitySum!$C$1300=0%,"",F29/ActivitySum!$C$1300) -> 0.00047635733 | J29: =IF(G29/ActivitySum!$C$1300=0%,"",G29/ActivitySum!$C$1300) -> 0.00010122925 | K29: =IFERROR(G29/E29,"") -> 0.21250696 | L29: =IFERROR(G29/F29,"") -> 0.21250696
C30: Z1-C-CON-2560 | D30: Pour Concrete - Z1 - Raft | E30: 1004127 | F30: 1004127 | G30: 213377 | H30: =IFERROR(F30/E30,"") -> 1 | I30: =IF(F30/ActivitySum!$C$1300=0%,"",F30/ActivitySum!$C$1300) -> 0.011575791 | J30: =IF(G30/ActivitySum!$C$1300=0%,"",G30/ActivitySum!$C$1300) -> 0.0024598557 | K30: =IFERROR(G30/E30,"") -> 0.21250001 | L30: =IFERROR(G30/F30,"") -> 0.21250001
C31: Z1-C-CON-2570 | D31: Fix Rebar Core Walls - Z1 - B2 | E31: 49489 | F31: 49489 | G31: 10516 | H31: =IFERROR(F31/E31,"") -> 1 | I31: =IF(F31/ActivitySum!$C$1300=0%,"",F31/ActivitySum!$C$1300) -> 0.00057051978 | J31: =IF(G31/ActivitySum!$C$1300=0%,"",G31/ActivitySum!$C$1300) -> 0.0001212307 | K31: =IFERROR(G31/E31,"") -> 0.21249166 | L31: =IFERROR(G31/F31,"") -> 0.21249166
... C79: Z1-C-CON-5950 | D79: Pour Concrete Core Walls Ramp - Z1 - B1 | E79: 37210 | F79: 37210 | G79: 31628 | H79: =IFERROR(F79/E79,"") -> 1 | I79: =IF(F79/ActivitySum!$C$1300=0%,"",F79/ActivitySum!$C$1300) -> 0.00042896484 | J79: =IF(G79/ActivitySum!$C$1300=0%,"",G79/ActivitySum!$C$1300) -> 0.00036461435 | K79: =IFERROR(G79/E79,"") -> 0.84998656 | L79: =IFERROR(G79/F79,"") -> 0.84998656
B80: Div 04 | C80: Z1-C-FIN-5790 | D80: Masonry Works - Z1 - B2 | E80: 3061 | F80: 3061 | G80: 184 | H80: =IFERROR(F80/E80,"") -> 1 | I80: =IF(F80/ActivitySum!$C$1300=0%,"",F80/ActivitySum!$C$1300) -> 3.5287863e-05 | J80: =IF(G80/ActivitySum!$C$1300=0%,"",G80/ActivitySum!$C$1300) -> 2.1211914e-06 | K80: =IFERROR(G80/E80,"") -> 0.060111075 | L80: =IFERROR(G80/F80,"") -> 0.060111075
B81: Div 10 | C81: Z1-C-CON-2540 | D81: Fix MEP Provisions - Z1 - Raft | E81: 21000 | F81: 21000 | G81: 4463 | H81: =IFERROR(F81/E81,"") -> 1 | I81: =IF(F81/ActivitySum!$C$1300=0%,"",F81/ActivitySum!$C$1300) -> 0.00024209249 | J81: =IF(G81/ActivitySum!$C$1300=0%,"",G81/ActivitySum!$C$1300) -> 5.1450419e-05 | K81: =IFERROR(G81/E81,"") -> 0.21252381 | L81: =IFERROR(G81/F81,"") -> 0.21252381
B82: Div 15 | C82: Z1-C-MEP-5810 | D82: Fix G.I Box and conduits - Z1 - B2 | E82: 26755 | F82: 15289 | G82: 14113 | H82: =IFERROR(F82/E82,"") -> 0.57144459 | I82: =IF(F82/ActivitySum!$C$1300=0%,"",F82/ActivitySum!$C$1300) -> 0.00017625486 | J82: =IF(G82/ActivitySum!$C$1300=0%,"",G82/ActivitySum!$C$1300) -> 0.00016269768 | K82: =IFERROR(G82/E82,"") -> 0.52749019 | L82: =IFERROR(G82/F82,"") -> 0.92308195
A83: Z2 | B83: Div 01 | C83: PRL-RCR-6980 | D83: Recurring Preliminaries through out the project | E83: 4687620 | F83: 1977131 | G83: 15348714 | H83: =IFERROR(F83/E83,"") -> 0.42177715 | I83: =IF(F83/ActivitySum!$C$1300=0%,"",F83/ActivitySum!$C$1300) -> 0.022792789 | J83: =IF(G83/ActivitySum!$C$1300=0%,"",G83/ActivitySum!$C$1300) -> 0.17694326 | K83: =IFERROR(G83/E83,"") -> 3.2743085 | L83: =IFERROR(G83/F83,"") -> 7.7631244
B84: Div 02 | C84: C-EW-10400 | D84: Excavation Stage 2 - Z2&3 | E84: 440461 | F84: 440461 | G84: 285198 | H84: =IFERROR(F84/E84,"") -> 1 | I84: =IF(F84/ActivitySum!$C$1300=0%,"",F84/ActivitySum!$C$1300) -> 0.0050777286 | J84: =IF(G84/ActivitySum!$C$1300=0%,"",G84/ActivitySum!$C$1300) -> 0.0032878236 | K84: =IFERROR(G84/E84,"") -> 0.64749887 | L84: =IFERROR(G84/F84,"") -> 0.64749887
C85: C-EW-10430 | D85: Strut Pipe Bracing - Z2&3 | E85: 254480 | F85: 254480 | G85: 216308 | H85: =IFERROR(F85/E85,"") -> 1 | I85: =IF(F85/ActivitySum!$C$1300=0%,"",F85/ActivitySum!$C$1300) -> 0.0029336999 | J85: =IF(G85/ActivitySum!$C$1300=0%,"",G85/ActivitySum!$C$1300) -> 0.0024936449 | K85: =IFERROR(G85/E85,"") -> 0.85 | L85: =IFERROR(G85/F85,"") -> 0.85
C86: C-EW-10440 | D86: Excavation Stage 1 - Z2&3 | E86: 348229 | F86: 348229 | G86: 212669 | H86: =IFERROR(F86/E86,"") -> 1 | I86: =IF(F86/ActivitySum!$C$1300=0%,"",F86/ActivitySum!$C$1300) -> 0.0040144584 | J86: =IF(G86/ActivitySum!$C$1300=0%,"",G86/ActivitySum!$C$1300) -> 0.0024516937 | K86: =IFERROR(G86/E86,"") -> 0.61071594 | L86: =IFERROR(G86/F86,"") -> 0.61071594
C87: C-SHRNG-DCE-C-2360 | D87: Place Guide Wall - Z2&3 | E87: 162250 | F87: 162250 | G87: 178476 | H87: =IFERROR(F87/E87,"") -> 1 | I87: =IF(F87/ActivitySum!$C$1300=0%,"",F87/ActivitySum!$C$1300) -> 0.0018704527 | J87: =IF(G87/ActivitySum!$C$1300=0%,"",G87/ActivitySum!$C$1300) -> 0.0020575095 | K87: =IFERROR(G87/E87,"") -> 1.1000062 | L87: =IFERROR(G87/F87,"") -> 1.1000062
C88: C-SHRNG-DCE-C-2370 | D88: Install Shoring System - Z2&3 | E88: 2987501 | F88: 2987500 | G88: 1643125 | H88: =IFERROR(F88/E88,"") -> 0.99999967 | I88: =IF(F88/ActivitySum!$C$1300=0%,"",F88/ActivitySum!$C$1300) -> 0.034440539 | J88: =IF(G88/ActivitySum!$C$1300=0%,"",G88/ActivitySum!$C$1300) -> 0.018942297 | K88: =IFERROR(G88/E88,"") -> 0.54999982 | L88: =IFERROR(G88/F88,"") -> 0.55
...

Sheet Weekly Cost Summary
A1: Project Name | F1: Weekly Progress Cost Summary | N1: Data Date: | P1: =INDEX(WeekDates[WeekDates],MATCH('Weekly Cost Summary'!$P$2,WeekDates[WeekID],)) -> 44192
A2: Location | N2: Current Week | P2: =MAX(U:U) -> 48
A3: BOQ Item Wise Summary | N3: Total Weeks | P3: 114
A4: 1817-BOQ Summary | B4: Budget Cost (AED) | C4: Planned Cost (AED) | D4: Earned Cost (AED) | E4: Planned Cost % | F4: Actual Cost % | I4: =A4 -> 1817-BOQ Summary | J4: =B4 -> Budget Cost (AED) | K4: =C4 -> Planned Cost (AED) | L4: =D4 -> Earned Cost (AED) | M4: =E4 -> Planned Cost %
A5: Div 01 | B5: 5594621 | C5: 2884132 | D5: 16042570 | E5: =C5/B5 -> 0.51551875 | F5: =D5/B5 -> 2.867499 | I5: =A5 -> Div 01 | J5: =B5 -> 5594621 | K5: =C5 -> 2884132 | L5: =D5 -> 16042570 | M5: =E5 -> 0.51551875
A6: Div 02 | B6: 8101845 | C6: 7902343 | D6: 6076794 | E6: =C6/B6 -> 0.97537573 | F6: =D6/B6 -> 0.75005064 | I6: =A6 -> Div 02 | J6: =B6 -> 8101845 | K6: =C6 -> 7902343 | L6: =D6 -> 6076794 | M6: =E6 -> 0.97537573
A7: Div 03 | B7: 26658801 | C7: 13256744 | D7: 8407576 | E7: =C7/B7 -> 0.49727458 | F7: =D7/B7 -> 0.31537712 | I7: =A7 -> Div 03 | J7: =B7 -> 26658801 | K7: =C7 -> 13256744 | L7: =D7 -> 8407576 | M7: =E7 -> 0.49727458 | U7: Row Labels | V7: Sum of WeekID
A8: Div 04 | B8: 1709702 | C8: 3061 | D8: 142628 | E8: =C8/B8 -> 0.0017903705 | F8: =D8/B8 -> 0.083422725 | I8: =A8 -> Div 04 | J8: =B8 -> 1709702 | K8: =C8 -> 3061 | L8: =D8 -> 142628 | M8: =E8 -> 0.0017903705 | U8: 1 | V8: 1
A9: Div 05 | B9: 432738 | D9: 210 | E9: =C9/B9 -> 0 | F9: =D9/B9 -> 0.00048528209 | I9: =A9 -> Div 05 | J9: =B9 -> 432738 | K9: =C9 -> 0 | L9: =D9 -> 210 | M9: =E9 -> 0 | U9: 2 | V9: 2
A10: Div 06 | B10: 358000 | E10: =C10/B10 -> 0 | F10: =D10/B10 -> 0 | I10: =A10 -> Div 06 | J10: =B10 -> 358000 | K10: =C10 -> 0 | L10: =D10 -> 0 | M10: =E10 -> 0 | U10: 3 | V10: 3
A11: Div 07 | B11: 1024731 | E11: =C11/B11 -> 0 | F11: =D11/B11 -> 0 | I11: =A11 -> Div 07 | J11: =B11 -> 1024731 | K11: =C11 -> 0 | L11: =D11 -> 0 | M11: =E11 -> 0 | U11: 4 | V11: 4
A12: Div 08 | B12: 2748699 | D12: 66857 | E12: =C12/B12 -> 0 | F12: =D12/B12 -> 0.024323143 | I12: =A12 -> Div 08 | J12: =B12 -> 2748699 | K12: =C12 -> 0 | L12: =D12 -> 66857 | M12: =E12 -> 0 | U12: 5 | V12: 5
A13: Div 09 | B13: 8267790 | D13: 364084 | E13: =C13/B13 -> 0 | F13: =D13/B13 -> 0.044036435 | I13: =A13 -> Div 09 | J13: =B13 -> 8267790 | K13: =C13 -> 0 | L13: =D13 -> 364084 | M13: =E13 -> 0 | U13: 6 | V13: 6
A14: Div 10 | B14: 2348697 | C14: 42000 | D14: 72343 | E14: =C14/B14 -> 0.017882256 | F14: =D14/B14 -> 0.030801334 | I14: =A14 -> Div 10 | J14: =B14 -> 2348697 | K14: =C14 -> 42000 | L14: =D14 -> 72343 | M14: =E14 -> 0.017882256 | U14: 7 | V14: 7
A15: Div 11 | B15: 1781708 | D15: 155177 | E15: =C15/B15 -> 0 | F15: =D15/B15 -> 0.087094518 | I15: =A15 -> Div 11 | J15: =B15 -> 1781708 | K15: =C15 -> 0 | L15: =D15 -> 155177 | M15: =E15 -> 0 | U15: 8 | V15: 8
A16: Div 12 | B16: 10893557 | D16: 704077 | E16: =C16/B16 -> 0 | F16: =D16/B16 -> 0.064632424 | I16: =A16 -> Div 12 | J16: =B16 -> 10893557 | K16: =C16 -> 0 | L16: =D16 -> 704077 | M16: =E16 -> 0 | U16: 9 | V16: 9
A17: Div 13 | B17: 3801981 | E17: =C17/B17 -> 0 | F17: =D17/B17 -> 0 | I17: =A17 -> Div 13 | J17: =B17 -> 3801981 | K17: =C17 -> 0 | L17: =D17 -> 0 | M17: =E17 -> 0 | U17: 10 | V17: 10
A18: Div 14 | B18: 148097 | E18: =C18/B18 -> 0 | F18: =D18/B18 -> 0 | I18: =A18 -> Div 14 | J18: =B18 -> 148097 | K18: =C18 -> 0 | L18: =D18 -> 0 | M18: =E18 -> 0 | U18: 11 | V18: 11
A19: Div 15 | B19: 12872739 | C19: 15289 | D19: 397660 | E19: =C19/B19 -> 0.0011877037 | F19: =D19/B19 -> 0.030891639 | I19: =A19 -> Div 15 | J19: =B19 -> 12872739 | K19: =C19 -> 15289 | L19: =D19 -> 397660 | M19: =E19 -> 0.0011877037 | U19: 12 | V19: 12
A20: Grand Total | B20: 86743706 | C20: 24103569 | D20: 32429976 | E20: =C20/B20 -> 0.2778711 | F20: =D20/B20 -> 0.3738597 | I20: =A20 -> Grand Total | J20: =B20 -> 86743706 | K20: =C20 -> 24103569 | L20: =D20 -> 32429976 | M20: =E20 -> 0.2778711 | U20: 13 | V20: 13
U21: 14 | V21: 14
A22: Trade Item Wise Summary | U22: 15 | V22: 15
A23: 1817-Trade | B23: Budget Cost (AED) | C23: Planned Cost (AED) | D23: Earned Cost (AED) | E23: Planned Cost % | F23: Actual Cost % | I23: =A23 -> 1817-Trade | J23: =B23 -> Budget Cost (AED) | K23: =C23 -> Planned Cost (AED) | L23: =D23 -> Earned Cost (AED) | M23: =E23 -> Planned Cost % | N23: =F23 -> Actual Cost % | U23: 16 | V23: 16
A24: Anti-Fungal & Carbonation | B24: 572734 | D24: 184292 | E24: =C24/B24 -> 0 | F24: =D24/B24 -> 0.3217759 | I24: =A24 -> Anti-Fungal & Carbonation | J24: =B24 -> 572734 | K24: =C24 -> 0 | L24: =D24 -> 184292 | M24: =E24 -> 0 | N24: =F24 -> 0.3217759 | U24: 17 | V24: 17
A25: Ceramic | B25: 355680 | E25: =C25/B25 -> 0 | F25: =D25/B25 -> 0 | I25: =A25 -> Ceramic | J25: =B25 -> 355680 | K25: =C25 -> 0 | L25: =D25 -> 0 | M25: =E25 -> 0 | N25: =F25 -> 0 | U25: 18 | V25: 18
A26: Concrete | B26: 26658801 | C26: 13256744 | D26: 8407576 | E26: =C26/B26 -> 0.49727458 | F26: =D26/B26 -> 0.31537712 | I26: =A26 -> Concrete | J26: =B26 -> 26658801 | K26: =C26 -> 13256744 | L26: =D26 -> 8407576 | M26: =E26 -> 0.49727458 | N26: =F26 -> 0.31537712 | U26: 19 | V26: 19
A27: Conveying System | B27: 3801981 | E27: =C27/B27 -> 0 | F27: =D27/B27 -> 0 | I27: =A27 -> Conveying System | J27: =B27 -> 3801981 | K27: =C27 -> 0 | L27: =D27 -> 0 | M27: =E27 -> 0 | N27: =F27 -> 0 | U27: 20 | V27: 20
A28: Doors | B28: 969680 | D28: 66857 | E28: =C28/B28 -> 0 | F28: =D28/B28 -> 0.068947488 | I28: =A28 -> Doors | J28: =B28 -> 969680 | K28: =C28 -> 0 | L28: =D28 -> 66857 | M28: =E28 -> 0 | N28: =F28 -> 0.068947488 | U28: 21 | V28: 21
A29: Electrical | B29: 12872739 | C29: 15289 | D29: 397660 | E29: =C29/B29 -> 0.0011877037 | F29: =D29/B29 -> 0.030891639 | I29: =A29 -> Electrical | J29: =B29 -> 12872739 | K29: =C29 -> 15289 | L29: =D29 -> 397660 | M29: =E29 -> 0.0011877037 | N29: =F29 -> 0.030891639 | U29: 22 | V29: 22
A30: Epoxy & Traffic Coating | B30: 975846 | D30: 6766 | E30: =C30/B30 -> 0 | F30: =D30/B30 -> 0.0069334711 | I30: =A30 -> Epoxy & Traffic Coating | J30: =B30 -> 975846 | K30: =C30 -> 0 | L30: =D30 -> 6766 | M30: =E30 -> 0 | N30: =F30 -> 0.0069334711 | U30: 23 | V30: 23
A31: False Ceiling | B31: 1052294 | D31: 448 | E31: =C31/B31 -> 0 | F31: =D31/B31 -> 0.00042573653 | I31: =A31 -> False Ceiling | J31: =B31 -> 1052294 | K31: =C31 -> 0 | L31: =D31 -> 448 | M31: =E31 -> 0 | N31: =F31 -> 0.00042573653 | U31: 24 | V31: 24
A32: Fire Fighting | B32: 1781708 | D32: 155177 | E32: =C32/B32 -> 0 | F32: =D32/B32 -> 0.087094518 | I32: =A32 -> Fire Fighting | J32: =B32 -> 1781708 | K32: =C32 -> 0 | L32: =D32 -> 155177 | M32: =E32 -> 0 | N32: =F32 -> 0.087094518 | U32: 25 | V32: 25
A33: Glazing | B33: 1644464 | E33: =C33/B33 -> 0 | F33: =D33/B33 -> 0 | I33: =A33 -> Glazing | J33: =B33 -> 1644464 | K33: =C33 -> 0 | L33: =D33 -> 0 | M33: =E33 -> 0 | N33: =F33 -> 0 | U33: 26 | V33: 26
A34: HVAC | B34: 10893557 | D34: 704077 | E34: =C34/B34 -> 0 | F34: =D34/B34 -> 0.064632424 | I34: =A34 -> HVAC | J34: =B34 -> 10893557 | K34: =C34 -> 0 | L34: =D34 -> 704077 | M34: =E34 -> 0 | N34: =F34 -> 0.064632424 | U34: 27 | V34: 27
A35: LPG System | B35: 148097 | E35: =C35/B35 -> 0 | F35: =D35/B35 -> 0 | I35: =A35 -> LPG System | J35: =B35 -> 148097 | K35: =C35 -> 0 | L35: =D35 -> 0 | M35: =E35 -> 0 | N35: =F35 -> 0 | U35: 28 | V35: 28
A36: Masonry | B36: 1709702 | C36: 3061 | D36: 142628 | E36: =C36/B36 -> 0.0017903705 | F36: =D36/B36 -> 0.083422725 | I36: =A36 -> Masonry | J36: =B36 -> 1709702 | K36: =C36 -> 3061 | L36: =D36 -> 142628 | M36: =E36 -> 0.0017903705 | N36: =F36 -> 0.083422725 | U36: 29 | V36: 29
A37: Natural Stone | B37: 2149353 | E37: =C37/B37 -> 0 | F37: =D37/B37 -> 0 | I37: =A37 -> Natural Stone | J37: =B37 -> 2149353 | K37: =C37 -> 0 | L37: =D37 -> 0 | M37: =E37 -> 0 | N37: =F37 -> 0 | U37: 30 | V37: 30
A38: Others Finishes | B38: 2559272 | D38: 210 | E38: =C38/B38 -> 0 | F38: =D38/B38 -> 8.2054584e-05 | I38: =A38 -> Others Finishes | J38: =B38 -> 2559272 | K38: =C38 -> 0 | L38: =D38 -> 210 | M38: =E38 -> 0 | N38: =F38 -> 8.2054584e-05 | U38: 31 | V38: 31
A39: Paint | B39: 354486 | D39: 38876 | E39: =C39/B39 -> 0 | F39: =D39/B39 -> 0.10966865 | I39: =A39 -> Paint | J39: =B39 -> 354486 | K39: =C39 -> 0 | L39: =D39 -> 38876 | M39: =E39 -> 0 | N39: =F39 -> 0.10966865 | U39: 32 | V39: 32
A40: Plaster | B40: 908192 | D40: 126439 | E40: =C40/B40 -> 0 | F40: =D40/B40 -> 0.13922056 | I40: =A40 -> Plaster | J40: =B40 -> 908192 | K40: =C40 -> 0 | L40: =D40 -> 126439 | M40: =E40 -> 0 | N40: =F40 -> 0.13922056 | U40: 33 | V40: 33
...

Sheet WeeklyPlanned
A1: ='Weekly Cost Summary'!A1 -> Project Name | G1: ='Weekly Cost Summary'!N1 -> Data Date: | I1: ='Weekly Cost Summary'!P1 -> 44192 | P1: Note: This report is not for printing, use it for only analysis purpose
A2: ='Weekly Cost Summary'!A2 -> Location | G2: ='Weekly Cost Summary'!N2 -> Current Week | I2: ='Weekly Cost Summary'!P2 -> 48
G3: ='Weekly Cost Summary'!N3 -> Total Weeks | I3: ='Weekly Cost Summary'!P3 -> 114
A4: Sum of WeeklyPlannedCost | B4: Week ID
A5: Row Labels | B5: 1 | C5: 2 | D5: 3 | E5: 4 | F5: 5 | G5: 6 | H5: 7 | I5: 8 | J5: 9 | K5: 10 | L5: 11 | M5: 12 | N5: 13 | O5: 14 | P5: 15 | Q5: 16 | R5: 17 | S5: 18 | T5: 19 | U5: 20 | V5: 21 | W5: 22 | X5: 23 | Y5: 24 | Z5: 25 | AA5: 26 | AB5: 27 | AC5: 28 | AD5: 29 | AE5: 30 | AF5: 31 | AG5: 32 | AH5: 33 | AI5: 34 | AJ5: 35 | AK5: 36 | AL5: 37 | AM5: 38 | AN5: 39 | AO5: 40 | AP5: 41 | AQ5: 42 | AR5: 43 | AS5: 44 | AT5: 45 | AU5: 46 | AV5: 47 | AW5: 48 | AX5: 49 | AY5: 50 | AZ5: 51 | BA5: 52 | BB5: 53 | BC5: 54 | BD5: 55 | BE5: 56 | BF5: 57 | BG5: 58 | BH5: 59 | BI5: 60 | BJ5: 61 | BK5: 62 | BL5: 63 | BM5: 64 | BN5: 65 | BO5: 66 | BP5: 67 | BQ5: 68 | BR5: 69 | BS5: 70 | BT5: 71 | BU5: 72 | BV5: 73 | BW5: 74 | BX5: 75 | BY5: 76 | BZ5: 77 | CA5: 78 | CB5: 79 | CC5: 80 | CD5: 81 | CE5: 82 | CF5: 83 | CG5: 84 | CH5: 85 | CI5: 86 | CJ5: 87 | CK5: 88 | CL5: 89 | CM5: 90 | CN5: 91 | CO5: 92 | CP5: 93 | CQ5: 94 | CR5: 95 | CS5: 96 | CT5: 97 | CU5: 98 | CV5: 99 | CW5: 100 | CX5: 101 | CY5: 102 | CZ5: 103 | DA5: 104 | DB5: 105 | DC5: 106 | DD5: 107 | DE5: 108 | DF5: 109 | DG5: 110 | DH5: 111 | DI5: 112 | DJ5: 113 | DK5: Grand Total
A6: Div 01 | B6: 399657 | C6: 343402 | D6: 293013 | E6: 41068 | F6: 41068 | G6: 41068 | H6: 41068 | I6: 41068 | J6: 41068 | K6: 41068 | L6: 41068 | M6: 41068 | N6: 41068 | O6: 41068 | P6: 41068 | Q6: 41068 | R6: 41068 | S6: 41068 | T6: 41068 | U6: 41068 | V6: 41068 | W6: 41068 | X6: 41068 | Y6: 41068 | Z6: 41068 | AA6: 41068 | AB6: 41068 | AC6: 41068 | AD6: 41068 | AE6: 41068 | AF6: 41068 | AG6: 41068 | AH6: 41068 | AI6: 41068 | AJ6: 41068 | AK6: 41068 | AL6: 41068 | AM6: 41068 | AN6: 41068 | AO6: 41068 | AP6: 41068 | AQ6: 41068 | AR6: 41068 | AS6: 41068 | AT6: 41068 | AU6: 41068 | AV6: 41068 | AW6: 41068 | AX6: 41068 | AY6: 41068 | AZ6: 41068 | BA6: 41068 | BB6: 41068 | BC6: 41068 | BD6: 41068 | BE6: 41068 | BF6: 41068 | BG6: 41068 | BH6: 41068 | BI6: 41068 | BJ6: 41068 | BK6: 41068 | BL6: 41068 | BM6: 41068 | BN6: 41068 | BO6: 41068 | BP6: 41068 | BQ6: 41068 | BR6: 41068 | BS6: 41068 | BT6: 41068 | BU6: 41068 | BV6: 41068 | BW6: 41068 | BX6: 41068 | BY6: 41068 | BZ6: 41068 | CA6: 41068 | CB6: 41068 | CC6: 41068 | CD6: 41068 | CE6: 41068 | CF6: 41068 | CG6: 41068 | CH6: 41068 | CI6: 41068 | CJ6: 41068 | CK6: 41068 | CL6: 41068 | CM6: 41068 | CN6: 41068 | CO6: 41068 | CP6: 41068 | CQ6: 41068 | CR6: 41068 | CS6: 41068 | CT6: 41068 | CU6: 41068 | CV6: 41068 | CW6: 41068 | CX6: 41068 | CY6: 41068 | CZ6: 41068 | DA6: 41068 | DB6: 41068 | DC6: 41068 | DD6: 41068 | DE6: 41068 | DF6: 41068 | DG6: 41068 | DH6: 41068 | DI6: 41068 | DJ6: 82136 | DK6: 5594620
A7: Div 02 | B7: 37445 | C7: 83238 | D7: 63596 | E7: 65947 | F7: 97350 | G7: 48675 | H7: 736404 | I7: 801304 | J7: 926172 | K7: 855389 | L7: 880926 | M7: 907266 | N7: 711928 | O7: 284140 | P7: 270956 | Q7: 252879 | R7: 134040 | S7: 195164 | T7: 164121 | U7: 110115 | V7: 110115 | W7: 110115 | X7: 55058 | CV7: 66500 | CW7: 83125 | CX7: 49875 | DK7: 8101843
A8: Div 03 | R8: 60808 | S8: 160110 | T8: 82367 | U8: 102591 | V8: 200574 | W8: 227653 | X8: 441360 | Y8: 402218 | Z8: 1189865 | AA8: 103749 | AB8: 241187 | AC8: 1015923 | AD8: 710463 | AE8: 499206 | AF8: 297029 | AG8: 870568 | AH8: 429304 | AI8: 520711 | AJ8: 1095272 | AK8: 212253 | AL8: 254008 | AM8: 346374 | AN8: 302519 | AO8: 434363 | AP8: 278227 | AQ8: 323802 | AR8: 520016 | AS8: 138241 | AT8: 365514 | AU8: 709434 | AV8: 313272 | AW8: 407763 | AX8: 634449 | AY8: 392444 | AZ8: 617825 | BA8: 403528 | BB8: 623397 | BC8: 439392 | BD8: 553885 | BE8: 357886 | BF8: 499755 | BG8: 324699 | BH8: 306656 | BI8: 576046 | BJ8: 310296 | BK8: 730982 | BL8: 348162 | BM8: 884597 | BN8: 329619 | BO8: 270932 | BP8: 265517 | BQ8: 182736 | BR8: 254560 | BS8: 251168 | BT8: 558899 | BU8: 383608 | BV8: 742782 | BW8: 496689 | BX8: 615602 | BY8: 514046 | BZ8: 39364 | CA8: 157083 | CB8: 91611 | CC8: 41318 | CD8: 64203 | CE8: 87538 | CF8: 50783 | DK8: 26658801
A9: Div 04 | AU9: 612 | AV9: 1837 | AW9: 612 | BA9: 2756 | BB9: 7905 | BC9: 18203 | BD9: 6068 | BE9: 95758 | BF9: 95758 | BG9: 45571 | BH9: 27305 | BI9: 23171 | BJ9: 111718 | BK9: 111718 | BL9: 103391 | BM9: 61758 | BN9: 61758 | BO9: 10293 | BP9: 14879 | BQ9: 44637 | BR9: 44637 | BS9: 48418 | BT9: 72628 | BU9: 48418 | BW9: 108942 | BX9: 108942 | BY9: 54472 | BZ9: 19455 | CA9: 58365 | CB9: 49286 | CC9: 77820 | CD9: 93384 | CE9: 46692 | CF9: 9296 | CG9: 23239 | DK9: 1709702
A10: Div 05 | AX10: 600 | BF10: 600 | CK10: 30300 | CL10: 30300 | CM10: 10100 | CN10: 18877 | CO10: 47397 | CP10: 53961 | CQ10: 29682 | CR10: 12721 | CS10: 22114 | CT10: 61371 | CU10: 64595 | CV10: 15286 | CW10: 9167 | CX10: 11000 | CY10: 11000 | CZ10: 3667 | DK10: 432738
A11: Div 06 | CF11: 12786 | CG11: 76714 | CH11: 63929 | CI11: 25571 | CL11: 25571 | CM11: 89500 | CN11: 63929 | DK11: 358000
A12: Div 07 | BL12: 3898 | BR12: 3898 | BW12: 1949 | BX12: 5847 | CA12: 84837 | CB12: 143927 | CC12: 186704 | CD12: 7240 | CE12: 18100 | CF12: 1950 | CG12: 14804 | CH12: 179698 | CI12: 300645 | CJ12: 57590 | CK12: 9746 | CL12: 3898 | DK12: 1024731
A13: Div 08 | BA13: 20822 | BB13: 41643 | BG13: 10411 | BH13: 52053 | BI13: 104105 | BM13: 83284 | BN13: 20821 | BO13: 62463 | BS13: 62463 | BT13: 20821 | BU13: 41643 | BV13: 20822 | BX13: 41642 | BY13: 83284 | CA13: 20821 | CB13: 31232 | CC13: 31232 | CE13: 31232 | CF13: 10410 | CG13: 22335 | CH13: 221174 | CI13: 216058 | CJ13: 226558 | CK13: 219558 | CL13: 233498 | CM13: 197473 | CN13: 228361 | CO13: 234807 | CP13: 44148 | CQ13: 21317 | CR13: 8923 | CS13: 5205 | CT13: 20822 | CU13: 28009 | CV13: 29249 | DK13: 2748699
A14: Div 09 | AX14: 13950 | AY14: 27900 | AZ14: 28182 | BA14: 87557 | BB14: 36569 | BC14: 6975 | BD14: 41851 | BE14: 56618 | BF14: 50177 | BG14: 59241 | BH14: 218166 | BI14: 61973 | BJ14: 43024 | BK14: 57791 | BL14: 84183 | BM14: 67801 | BN14: 69819 | BO14: 53881 | BP14: 26710 | BQ14: 33932 | BR14: 47395 | BS14: 91147 | BT14: 81583 | BU14: 62791 | BV14: 83743 | BW14: 82174 | BX14: 56506 | BY14: 97239 | BZ14: 26295 | CA14: 110667 | CB14: 94726 | CC14: 211359 | CD14: 209279 | CE14: 248653 | CF14: 280559 | CG14: 374489 | CH14: 176017 | CI14: 309924 | CJ14: 181437 | CK14: 540884 | CL14: 477470 | CM14: 376499 | CN14: 421889 | CO14: 403965 | CP14: 416636 | CQ14: 336831 | CR14: 237068 | CS14: 64544 | CT14: 42597 | CU14: 64126 | CV14: 374400 | CW14: 117867 | CX14: 211990 | CY14: 98014 | CZ14: 112234 | DA14: 12809 | DB14: 5684 | DK14: 8267790
A15: Div 10 | Y15: 12600 | Z15: 8400 | AE15: 4375 | AF15: 5250 | AG15: 875 | AH15: 2625 | AI15: 5250 | AJ15: 2625 | BA15: 18956 | BB15: 58418 | BC15: 3105 | BD15: 3105 | BE15: 1035 | BG15: 2825 | BH15: 6442 | BI15: 5352 | BJ15: 5352 | BK15: 5352 | BL15: 9202 | BM15: 10208 | BN15: 75476 | BO15: 229418 | BP15: 113611 | BQ15: 223456 | BR15: 119121 | BS15: 11547 | BT15: 8094 | BU15: 8723 | BV15: 31300 | BW15: 58835 | BX15: 7876 | BY15: 13157 | BZ15: 5105 | CA15: 14474 | CB15: 10417 | CC15: 9811 | CD15: 4874 | CE15: 76137 | CF15: 23096 | CG15: 51607 | CH15: 51882 | CI15: 70447 | CJ15: 17594 | CK15: 15017 | CL15: 10730 | CM15: 162326 | CN15: 64429 | CO15: 43022 | CP15: 96839 | CQ15: 78900 | CR15: 64778 | CS15: 43186 | CV15: 32389 | CW15: 141521 | CX15: 69428 | CY15: 32667 | CZ15: 29667 | DA15: 22178 | DB15: 20526 | DC15: 13684 | DK15: 2348697
A16: Div 11 | BA16: 3905 | BB16: 23431 | BC16: 23431 | BD16: 23431 | BE16: 7810 | BG16: 1518 | BH16: 26065 | BI16: 56950 | BJ16: 44258 | BK16: 33912 | BL16: 42390 | BM16: 16956 | BN16: 12146 | BO16: 55450 | BP16: 25170 | BQ16: 37648 | BR16: 42390 | BS16: 25434 | BT16: 26952 | BU16: 34543 | BV16: 39994 | BW16: 21860 | BX16: 37922 | BY16: 54286 | BZ16: 21422 | CA16: 84527 | CB16: 79354 | CC16: 67075 | CD16: 85339 | CE16: 94255 | CF16: 88876 | CG16: 90465 | CH16: 44767 | CI16: 53755 | CJ16: 36096 | CK16: 60864 | CL16: 47260 | CM16: 16210 | CN16: 22628 | CO16: 11588 | CP16: 33871 | CQ16: 34560 | CR16: 18074 | CS16: 16416 | CT16: 20141 | CU16: 18416 | CV16: 6897 | CX16: 3143 | CY16: 3143 | CZ16: 3143 | DA16: 1571 | DK16: 1781708
A17: Div 12 | BA17: 14877 | BB17: 89261 | BC17: 89261 | BD17: 97526 | BE17: 40774 | BH17: 89260 | BI17: 193819 | BJ17: 181071 | BK17: 192297 | BL17: 240948 | BM17: 164903 | BN17: 65390 | BO17: 141607 | BP17: 59926 | BQ17: 94359 | BR17: 207927 | BS17: 118666 | BT17: 164180 | BU17: 223324 | BV17: 159583 | BW17: 143563 | BX17: 267970 | BY17: 189659 | BZ17: 31675 | CA17: 278024 | CB17: 275103 | CC17: 143653 | CD17: 243505 | CE17: 299702 | CF17: 194123 | CG17: 220375 | CH17: 1855956 | CI17: 1348180 | CJ17: 617931 | CK17: 701813 | CL17: 250951 | CM17: 98129 | CN17: 217477 | CO17: 80454 | CP17: 20473 | CQ17: 86448 | CR17: 253446 | CS17: 96135 | CT17: 123341 | CU17: 88176 | CX17: 23715 | CY17: 23715 | CZ17: 23715 | DA17: 23715 | DB17: 19761 | DC17: 11857 | DD17: 11857 | DJ17: 0 | DK17: 10893556
A18: Div 13 | CD18: 58338 | CE18: 58338 | CF18: 58338 | CG18: 68061 | CH18: 116676 | CI18: 204184 | CJ18: 106953 | CK18: 190294 | CL18: 198397 | CM18: 158578 | CN18: 266225 | CO18: 327342 | CP18: 232426 | CQ18: 215296 | CR18: 226871 | CS18: 166680 | CT18: 351188 | CU18: 235667 | CV18: 156263 | CW18: 118065 | CX18: 85722 | CY18: 85722 | CZ18: 112549 | DA18: 1428 | DB18: 952 | DC18: 952 | DD18: 476 | DK18: 3801981
A19: Div 14 | CA19: 13645 | CB19: 2880 | CC19: 2399 | CD19: 5965 | CE19: 12136 | CF19: 2880 | CG19: 12136 | CH19: 5965 | CI19: 1234 | CJ19: 13576 | CK19: 1234 | CM19: 9256 | CN19: 3085 | CO19: 12341 | CP19: 15426 | CQ19: 9256 | CR19: 3085 | CS19: 9256 | CT19: 6171 | CU19: 6171 | DK19: 148097
A20: Div 15 | AW20: 15289 | AX20: 11466 | BA20: 14047 | BB20: 91928 | BC20: 109588 | BD20: 69436 | BE20: 70570 | BF20: 31093 | BG20: 13520 | BH20: 44657 | BI20: 452548 | BJ20: 518902 | BK20: 118208 | BL20: 138345 | BM20: 98962 | BN20: 94854 | BO20: 282869 | BP20: 278729 | BQ20: 492985 | BR20: 671417 | BS20: 251316 | BT20: 119433 | BU20: 135324 | BV20: 174710 | BW20: 347448 | BX20: 194014 | BY20: 330340 | BZ20: 164639 | CA20: 224219 | CB20: 131214 | CC20: 173764 | CD20: 199901 | CE20: 209742 | CF20: 272626 | CG20: 954140 | CH20: 782131 | CI20: 789958 | CJ20: 263202 | CK20: 249808 | CL20: 235546 | CM20: 355338 | CN20: 614327 | CO20: 207787 | CP20: 446153 | CQ20: 440326 | CR20: 225141 | CS20: 230856 | CT20: 212481 | CU20: 253399 | CV20: 57855 | CW20: 1700 | CX20: 2040 | CY20: 1224 | CZ20: 408 | DA20: 408 | DB20: 408 | DJ20: 0 | DK20: 12872739
A21: Grand Total | B21: 437102 | C21: 426640 | D21: 356609 | E21: 107015 | F21: 138418 | G21: 89743 | H21: 777472 | I21: 842372 | J21: 967240 | K21: 896457 | L21: 921994 | M21: 948334 | N21: 752996 | O21: 325208 | P21: 312024 | Q21: 293947 | R21: 235916 | S21: 396342 | T21: 287556 | U21: 253774 | V21: 351757 | W21: 378836 | X21: 537486 | Y21: 455886 | Z21: 1239333 | AA21: 144817 | AB21: 282255 | AC21: 1056991 | AD21: 751531 | AE21: 544649 | AF21: 343347 | AG21: 912511 | AH21: 472997 | AI21: 567029 | AJ21: 1138965 | AK21: 253321 | AL21: 295076 | AM21: 387442 | AN21: 343587 | AO21: 475431 | AP21: 319295 | AQ21: 364870 | AR21: 561084 | AS21: 179309 | AT21: 406582 | AU21: 751114 | AV21: 356177 | AW21: 464732 | AX21: 701533 | AY21: 461412 | AZ21: 687075 | BA21: 607516 | BB21: 1013620 | BC21: 731023 | BD21: 836370 | BE21: 671519 | BF21: 718451 | BG21: 498853 | BH21: 811672 | BI21: 1515032 | BJ21: 1255689 | BK21: 1291328 | BL21: 1011587 | BM21: 1429537 | BN21: 770951 | BO21: 1147981 | BP21: 825610 | BQ21: 1150821 | BR21: 1432413 | BS21: 901227 | BT21: 1093658 | BU21: 979442 | BV21: 1294002 | BW21: 1302528 | BX21: 1377389 | BY21: 1377551 | BZ21: 349023 | CA21: 1087730 | CB21: 950818 | CC21: 986203 | CD21: 1013096 | CE21: 1223593 | CF21: 1046791 | CG21: 1949433 | CH21: 3539263 | CI21: 3361024 | CJ21: 1562005 | CK21: 2060586 | CL21: 1554689 | CM21: 1514477 | CN21: 1962295 | CO21: 1409771 | CP21: 1401001 | CQ21: 1293684 | CR21: 1091175 | CS21: 695460 | CT21: 879180 | CU21: 799627 | CV21: 779907 | CW21: 512513 | CX21: 497981 | CY21: 296553 | CZ21: 326451 | DA21: 103177 | DB21: 88399 | DC21: 67561 | DD21: 53401 | DE21: 41068 | DF21: 41068 | DG21: 41068 | DH21: 41068 | DI21: 41068 | DJ21: 82136 | DK21: 86743702
A68: Sum of Earned Hrs | B68: Column Labels
A69: Row Labels | B69: 1 | C69: 2 | D69: 3 | E69: 4 | F69: 5 | G69: 6 | H69: 7 | I69: 8 | J69: 9 | K69: 10 | L69: 11 | M69: 12 | N69: 13 | O69: 14 | P69: 15 | Q69: 16 | R69: 17 | S69: 18 | T69: 19 | U69: 20 | V69: 21 | W69: 22 | X69: 23 | Y69: 24 | Z69: 25 | AA69: 26 | AB69: 27 | AC69: 28 | AD69: 29 | AE69: 30 | AF69: 31 | AG69: 32 | AH69: 33 | AI69: 34 | AJ69: 35 | AK69: 36 | AL69: 37 | AM69: 38 | AN69: 39 | AO69: 40 | AP69: 41 | AQ69: 42 | AR69: 43 | AS69: 44 | AT69: 45 | AU69: 46 | AV69: 47 | AW69: 48 | AX69: 49 | AY69: 50 | AZ69: 51 | BA69: 52 | BB69: 53 | BC69: 54 | BD69: 55 | BE69: 56 | BF69: 57 | BG69: 58 | BH69: 59 | BI69: 60 | BJ69: 61 | BK69: 62 | BL69: 63 | BM69: 64 | BN69: 65 | BO69: 66 | BP69: 67 | BQ69: 68 | BR69: 69 | BS69: 70 | BT69: 71 | BU69: 72 | BV69: 73 | BW69: 74 | BX69: 75 | BY69: 76 | BZ69: 77 | CA69: 78 | CB69: 79 | CC69: Grand Total
A70: Div 01 | B70: 393 | CC70: 393
A71: Div 02 | B71: 272 | C71: 411 | D71: 4770 | E71: 2031 | F71: 3125 | H71: 207 | J71: 2173 | K71: 34 | CC71: 13023
A72: Div 03 | G72: 126 | H72: 162 | I72: 54 | J72: 1996 | K72: 1 | L72: 184 | M72: 0 | N72: 40 | O72: 2276 | P72: 1843 | Q72: 702 | R72: 1888 | S72: 9604 | T72: 4155 | U72: 15980 | V72: 7270 | W72: 6715 | X72: 10618 | Y72: 325 | Z72: 76 | AA72: 58 | AB72: 428 | AC72: 222 | AD72: 2205 | AE72: 4450 | AF72: 7749 | AG72: 684 | AH72: 1065 | AI72: 7331 | AJ72: 1952 | AK72: 820 | AL72: 1110 | AM72: 855 | AN72: 3374 | AO72: 9057 | AP72: 2148 | AQ72: 1624 | AR72: 2653 | AS72: 670 | AT72: 1903 | AU72: 2429 | AV72: 1861 | AW72: 149 | AX72: 1125 | AY72: 2547 | AZ72: 6829 | BA72: 18578 | BB72: 4858 | BC72: 5366 | BD72: 4686 | BE72: 1604 | BF72: 7088 | BG72: 7617 | BH72: 2756 | BI72: 12357 | BJ72: 6235 | BK72: 2854 | BL72: 5040 | BM72: 1252 | BN72: 292 | BO72: 968 | BP72: 1049 | BQ72: 489 | BR72: 64 | BS72: 148 | CC72: 212614
A73: Div 04 | AH73: 2 | AK73: 20 | AM73: 8 | AO73: 212 | AP73: 690 | AQ73: 690 | AT73: 140 | AZ73: 4146 | BA73: 4146 | BB73: 1300 | BD73: 217 | BF73: 2273 | BH73: 1782 | BJ73: 764 | BK73: 1908 | BM73: 777 | BO73: 532 | BP73: 2292 | BS73: 342 | CC73: 22241
A74: Div 05 | AJ74: 2 | AR74: 11 | BV74: 519 | BX74: 1839 | BY74: 1282 | BZ74: 1038 | CA74: 424 | CC74: 5115
