Workbook

Sheet LIST
B2: Detailed Schedule Checklist
C4: Project Name | D4: : | E4: Airfield Facilities Upgrades (AFU) - Phase 1
C5: Contract Number | D5: : | E5: =IF($E$4=$O$8,S$8,IF($E$4=$O$9,S$9,IF($E$4=$O$10,S$10,IF($E$4=$O$11,S$11,IF($E$4=$O$12,S$12,0))))) -> R-14-084-BF | K5: STATUS | M5: IF NO | O5: PROJECT NAME | Q5: PROJECT CODE | S5: CONTRACT NUMBER | U5: CONTRACTOR
C6: Project Code | D6: : | E6: =IF($E$4=$O$8,Q$8,IF($E$4=$O$9,Q$9,IF($E$4=$O$10,Q$10,IF($E$4=$O$11,Q$11,IF($E$4=$O$12,Q$12,0))))) -> RUH-CP-1402
C7: Contractor | D7: : | E7: =IF($E$4=$O$8,U$8,IF($E$4=$O$9,U$9,IF($E$4=$O$10,U$10,IF($E$4=$O$11,U$11,IF($E$4=$O$12,U$12,0))))) -> Almabani General Contractor
C8: Submittal Number | D8: : | K8: YES | M8: MAJOR | O8: Airfield Facilities Upgrades (AFU) - Phase 1 | Q8: RUH-CP-1402 | S8: R-14-084-BF | U8: Almabani General Contractor
C9: Submitted Date | D9: : | K9: NO | M9: MINOR | O9: Development & Expansion of Existing Terminals (T3) | Q9: RUH-CP-1501A | S9: R-00-074-DB-0 | U9: Riyadh Airport Contractor
C10: Revision | D10: : | K10: NA | O10: TR4 | Q10: RUH-CP-1501C | S10: R-13-067-SD-0 | U10: Riyadh Airport Contractor
C11: Date of Review | D11: : | O11: SCAHC ER | Q11: RUH-CP-1501B | S11: TO BE AWARDED | U11: Riyadh Airport Contractor
O12: LC3 | Q12: RUH-CP-1502 | S12: R-00-085-DB-0 | U12: Saudi Services of Electro-Mechanic
B13: S.No | C13: Description | F13: Status | G13: Fill only Colored | H13: Remarks
B14: A | C14: General
B15: 1 | C15: Is the Detailed schedule submitted within 60 days from commencement date? | F15: NO | G15: MINOR
B16: 2 | C16: Does the Title page or Footer / Header block show the followings:
B17: a | C17: Project Name, Contract Number and Project Code | F17: YES
B18: b | C18: Contractor Name/Logo | F18: YES
B19: c | C19: Client & Consultant Name/Logo | F19: NO | G19: MINOR | H19: KKIA Logo Missing
B20: d | C20: Data Date (Start Date of Contract) | F20: YES
B21: e | C21: Schedule Submittal Date (In Revision Box) | F21: NO | G21: MINOR | H21: No Revision tables in footer
B22: 3 | C22: Does the Contractor used latest version of Oracle Primavera as per specifications | F22: YES
B23: 4 | C23: Does Contractor follow the default settings in Primavera as per specifications as below:
B24: a | C24: Retained Logic | F24: YES
B25: b | C25: Early Start | F25: YES
B26: c | C26: Non Critical | F26: YES
B27: d | C27: Finish Float | F27: YES
B28: e | C28: Longest Path | F28: NO | G28: MINOR
B29: 5 | C29: Does Detailed Schedule complies with complete Contract time frame/Duration of the project | F29: YES
B30: 6 | C30: Does Detailed schedule is defined in detail reflecting entire scope of work | F30: YES
B31: 8 | C31: Does Detailed schedule shows the Project Phases/Zones/Levels as agreed | F31: YES
B32: 9 | C32: Does Primavera layout files (PLF) provided | F32: YES
B33: 10 | C33: Any other Information | F33: NA
B35: B | C35: Work Breakdown Structure (WBS)
B36: 1 | C36: Does WBS structure is inline with schedule guidelines provided by Engineer or as per Price Breakdown structure Uniformat Level | F36: NO | G36: MINOR
B37: 2 | C37: Does WBS Codes are inline with schedule guidelines provided by Engineer | F37: YES
B38: 3 | C38: Does Budgeted Cost at each WBS/Work package is inline with Price breakdown structure | F38: NO | G38: MINOR | H38: Primavera Bug error
B39: 4 | C39: Does Start/Finish dates for each WBS are inline with contractual requirements/mutually agreed by all | F39: NA
B40: 5 | C40: Does Project Budgeted Cost = Contract Price/Value | F40: NO | G40: MINOR | H40: Primavera Bug error
B41: 6 | C41: Any other Information | F41: NA
B43: C | C43: Activities
B44: 1 | C44: Does Activity duration is in workdays | F44: YES
...

Sheet DASHBOARD
B2: Detailed Schedule Checklist
H4: STATUS | K4: If NO
B5: Description | C5: YES | D5: NO | E5: NA | F5: MAJOR | G5: MINOR | H5: % YES | I5: % NO | J5: % NA | K5: % MAJOR | L5: % MINOR | N5: Weightage
B6: =LIST!C14 -> General | C6: =COUNTIF(LIST!$F14:$F34,DASHBOARD!C$5) -> 12 | D6: =COUNTIF(LIST!$F14:$F34,DASHBOARD!D$5) -> 4 | E6: =COUNTIF(LIST!$F14:$F34,DASHBOARD!E$5) -> 1 | F6: =COUNTIF(LIST!$G14:$G34,DASHBOARD!F$5) -> 0 | G6: =COUNTIF(LIST!$G14:$G34,DASHBOARD!G$5) -> 4 | H6: =IF(C6=0,0,C6/SUM($C6:$E6)) -> 0.70588235 | I6: =IF(D6=0,0,D6/SUM($C6:$E6)) -> 0.23529412 | J6: =IF(E6=0,0,E6/SUM($C6:$E6)) -> 0.058823529 | K6: =IF(F6=0,0,F6/SUM($F6:$G6)) -> 0 | L6: =IF(G6=0,0,G6/SUM($F6:$G6)) -> 1 | N6: 10
B7: =LIST!C35 -> Work Breakdown Structure (WBS) | C7: =COUNTIF(LIST!$F35:$F42,DASHBOARD!C$5) -> 1 | D7: =COUNTIF(LIST!$F35:$F42,DASHBOARD!D$5) -> 3 | E7: =COUNTIF(LIST!$F35:$F42,DASHBOARD!E$5) -> 2 | F7: =COUNTIF(LIST!$G35:$G42,DASHBOARD!F$5) -> 0 | G7: =COUNTIF(LIST!$G35:$G42,DASHBOARD!G$5) -> 3 | H7: =IF(C7=0,0,C7/SUM($C7:$E7)) -> 0.16666667 | I7: =IF(D7=0,0,D7/SUM($C7:$E7)) -> 0.5 | J7: =IF(E7=0,0,E7/SUM($C7:$E7)) -> 0.33333333 | K7: =IF(F7=0,0,F7/SUM($F7:$G7)) -> 0 | L7: =IF(G7=0,0,G7/SUM($F7:$G7)) -> 1 | N7: 20
B8: =LIST!C43 -> Activities | C8: =COUNTIF(LIST!$F43:$F127,DASHBOARD!C$5) -> 45 | D8: =COUNTIF(LIST!$F43:$F127,DASHBOARD!D$5) -> 18 | E8: =COUNTIF(LIST!$F43:$F127,DASHBOARD!E$5) -> 3 | F8: =COUNTIF(LIST!$G43:$G127,DASHBOARD!F$5) -> 7 | G8: =COUNTIF(LIST!$G43:$G127,DASHBOARD!G$5) -> 11 | H8: =IF(C8=0,0,C8/SUM($C8:$E8)) -> 0.68181818 | I8: =IF(D8=0,0,D8/SUM($C8:$E8)) -> 0.27272727 | J8: =IF(E8=0,0,E8/SUM($C8:$E8)) -> 0.045454545 | K8: =IF(F8=0,0,F8/SUM($F8:$G8)) -> 0.38888889 | L8: =IF(G8=0,0,G8/SUM($F8:$G8)) -> 0.61111111 | N8: 30
B9: =LIST!C128 -> Critical Path Method (CPM) | C9: =COUNTIF(LIST!$F128:$F134,DASHBOARD!C$5) -> 1 | D9: =COUNTIF(LIST!$F128:$F134,DASHBOARD!D$5) -> 3 | E9: =COUNTIF(LIST!$F128:$F134,DASHBOARD!E$5) -> 1 | F9: =COUNTIF(LIST!$G128:$G134,DASHBOARD!F$5) -> 1 | G9: =COUNTIF(LIST!$G128:$G134,DASHBOARD!G$5) -> 2 | H9: =IF(C9=0,0,C9/SUM($C9:$E9)) -> 0.2 | I9: =IF(D9=0,0,D9/SUM($C9:$E9)) -> 0.6 | J9: =IF(E9=0,0,E9/SUM($C9:$E9)) -> 0.2 | K9: =IF(F9=0,0,F9/SUM($F9:$G9)) -> 0.33333333 | L9: =IF(G9=0,0,G9/SUM($F9:$G9)) -> 0.66666667 | N9: 10
B10: =LIST!C135 -> Resources | C10: =COUNTIF(LIST!$F135:$F141,DASHBOARD!C$5) -> 3 | D10: =COUNTIF(LIST!$F135:$F141,DASHBOARD!D$5) -> 1 | E10: =COUNTIF(LIST!$F135:$F141,DASHBOARD!E$5) -> 1 | F10: =COUNTIF(LIST!$G135:$G141,DASHBOARD!F$5) -> 0 | G10: =COUNTIF(LIST!$G135:$G141,DASHBOARD!G$5) -> 1 | H10: =IF(C10=0,0,C10/SUM($C10:$E10)) -> 0.6 | I10: =IF(D10=0,0,D10/SUM($C10:$E10)) -> 0.2 | J10: =IF(E10=0,0,E10/SUM($C10:$E10)) -> 0.2 | K10: =IF(F10=0,0,F10/SUM($F10:$G10)) -> 0 | L10: =IF(G10=0,0,G10/SUM($F10:$G10)) -> 1 | N10: 30
B11: SUMMARY | C11: =SUM(C6:C10) -> 62 | D11: =SUM(D6:D10) -> 29 | E11: =SUM(E6:E10) -> 8 | F11: =SUM(F6:F10) -> 8 | G11: =SUM(G6:G10) -> 21 | H11: =SUMPRODUCT(H6:H10,N6:N10)/100 -> 0.50846702 | I11: =SUMPRODUCT(I6:I10,N6:N10)/100 -> 0.32534759 | J11: =SUMPRODUCT(J6:J10,N6:N10)/100 -> 0.16618538 | K11: =AVERAGE(K6:K10) -> 0.14444444 | L11: =AVERAGE(L6:L10) -> 0.85555556 | N11: =SUM(N6:N10) -> 100
B24: REMARKS/COMMENTS:
B25: 1. Schedule is Approved with Exceptions
B26: 2. Critical Path shall be defined a Longest Path
B27: 3. Procurement Activities Fabrication & FAT information to be provided
B28: 4
B29: 5
B30: 6
B31: 7
B32: 8
B33: 9
B34: 10

Sheet lEGEND
B3: LEGEND
C4: YES | D4: : | E4: Agreed/Mentioned as per requirements
C5: NO | D5: : | E5: Not Mentioned/ Not as per requirements
C6: NA | D6: : | E6: Not Applicable
C7: MAJOR | D7: : | E7: Not mentioned but strictly follow/fulfill as per requirements
C8: MINOR | D8: : | E8: Not Mentioned as per requirements but may be acceptable
